package com.shnupbups.allthethings.world;

import java.util.Random;

import net.minecraft.init.Blocks;
import net.minecraft.tileentity.TileEntityChest;
import net.minecraft.tileentity.TileEntityMobSpawner;
import net.minecraft.util.WeightedRandomChestContent;
import net.minecraft.world.World;
import net.minecraft.world.biome.BiomeGenOcean;
import net.minecraft.world.chunk.IChunkProvider;

import com.shnupbups.allthethings.init.ModMisc;

import cpw.mods.fml.common.IWorldGenerator;

public class WorldGenPirateShip implements IWorldGenerator {

	@Override
	public void generate(Random random, int chunkX, int chunkZ, World world, IChunkProvider chunkGenerator, IChunkProvider chunkProvider) {
		if(random.nextInt(100) <= 1) {
			int posX = chunkX*16;
			int posZ = chunkZ*16;
			int posY = world.getHeightValue(posX, posZ);
			if(world.provider.dimensionId == 0) {
				if(world.getBiomeGenForCoords(posX, posZ) instanceof BiomeGenOcean) {
					/**WorldHelper.fillAreaWithBlock(posX, posY, posZ, posX+25, posY+1, posZ, Blocks.planks, 0, 3, true, true);
					WorldHelper.fillAreaWithBlock(posX-1, posY, posZ-1, posX-1, posY+1, posZ-1, Blocks.planks, 0, 3, true, true);
					WorldHelper.fillAreaWithBlock(posX-2, posY, posZ-2, posX-2, posY+1, posZ-2, Blocks.planks, 0, 3, true, true);
					WorldHelper.fillAreaWithBlock(posX-3, posY, posZ-3, posX-3, posY+1, posZ-3, Blocks.planks, 0, 3, true, true);
					WorldHelper.fillAreaWithBlock(posX-4, posY, posZ-4, posX-4, posY+1, posZ-4, Blocks.planks, 0, 3, true, true);
					WorldHelper.fillAreaWithBlock(posX-5, posY, posZ-5, posX-5, posY+1, posZ-5, Blocks.planks, 0, 3, true, true);
					WorldHelper.fillAreaWithBlock(posX-5, posY, posZ-6, posX-5, posY+1, posZ-6, Blocks.planks, 0, 3, true, true);
					WorldHelper.fillAreaWithBlock(posX-4, posY, posZ-7, posX-4, posY+1, posZ-7, Blocks.planks, 0, 3, true, true);
					WorldHelper.fillAreaWithBlock(posX-3, posY, posZ-8, posX-3, posY+1, posZ-8, Blocks.planks, 0, 3, true, true);
					WorldHelper.fillAreaWithBlock(posX-2, posY, posZ-9, posX-2, posY+1, posZ-9, Blocks.planks, 0, 3, true, true);
					WorldHelper.fillAreaWithBlock(posX-1, posY, posZ-10, posX-1, posY+1, posZ-10, Blocks.planks, 0, 3, true, true);
					WorldHelper.fillAreaWithBlock(posX, posY, posZ-11, posX+25, posY+1, posZ-11, Blocks.planks, 0, 3, true, true);
					
					WorldHelper.fillAreaWithBlock(posX, posY+2, posZ+1, posX+25, posY+4, posZ+1, Blocks.planks, 0, 3, true, true);
					WorldHelper.fillAreaWithBlock(posX-1, posY+2, posZ, posX-1, posY+4, posZ, Blocks.planks, 0, 3, true, true);
					WorldHelper.fillAreaWithBlock(posX-2, posY+2, posZ-1, posX-2, posY+4, posZ-1, Blocks.planks, 0, 3, true, true);
					WorldHelper.fillAreaWithBlock(posX-3, posY+2, posZ-2, posX-3, posY+4, posZ-2, Blocks.planks, 0, 3, true, true);
					WorldHelper.fillAreaWithBlock(posX-4, posY+2, posZ-3, posX-4, posY+4, posZ-3, Blocks.planks, 0, 3, true, true);
					WorldHelper.fillAreaWithBlock(posX-5, posY+2, posZ-4, posX-5, posY+4, posZ-4, Blocks.planks, 0, 3, true, true);
					WorldHelper.fillAreaWithBlock(posX-6, posY+2, posZ-5, posX-6, posY+4, posZ-5, Blocks.planks, 0, 3, true, true);
					WorldHelper.fillAreaWithBlock(posX-6, posY+2, posZ-6, posX-6, posY+4, posZ-6, Blocks.planks, 0, 3, true, true);
					WorldHelper.fillAreaWithBlock(posX-5, posY+2, posZ-7, posX-5, posY+4, posZ-7, Blocks.planks, 0, 3, true, true);
					WorldHelper.fillAreaWithBlock(posX-4, posY+2, posZ-8, posX-4, posY+4, posZ-8, Blocks.planks, 0, 3, true, true);
					WorldHelper.fillAreaWithBlock(posX-3, posY+2, posZ-9, posX-3, posY+4, posZ-9, Blocks.planks, 0, 3, true, true);
					WorldHelper.fillAreaWithBlock(posX-2, posY+2, posZ-10, posX-2, posY+4, posZ-10, Blocks.planks, 0, 3, true, true);
					WorldHelper.fillAreaWithBlock(posX-1, posY+2, posZ-11, posX-1, posY+4, posZ-11, Blocks.planks, 0, 3, true, true);
					WorldHelper.fillAreaWithBlock(posX, posY+2, posZ-12, posX+25, posY+4, posZ-12, Blocks.planks, 0, 3, true, true);
					
					WorldHelper.fillAreaWithBlock(posX, posY+5, posZ+2, posX+25, posY+8, posZ+2, Blocks.planks, 0, 3, true, true);
					WorldHelper.fillAreaWithBlock(posX-1, posY+5, posZ+1, posX-1, posY+8, posZ+1, Blocks.planks, 0, 3, true, true);
					WorldHelper.fillAreaWithBlock(posX-2, posY+5, posZ, posX-2, posY+8, posZ, Blocks.planks, 0, 3, true, true);
					WorldHelper.fillAreaWithBlock(posX-3, posY+5, posZ-1, posX-3, posY+8, posZ-1, Blocks.planks, 0, 3, true, true);
					WorldHelper.fillAreaWithBlock(posX-4, posY+5, posZ-2, posX-4, posY+8, posZ-2, Blocks.planks, 0, 3, true, true);
					WorldHelper.fillAreaWithBlock(posX-5, posY+5, posZ-3, posX-5, posY+8, posZ-3, Blocks.planks, 0, 3, true, true);
					WorldHelper.fillAreaWithBlock(posX-6, posY+5, posZ-4, posX-6, posY+8, posZ-4, Blocks.planks, 0, 3, true, true);
					WorldHelper.fillAreaWithBlock(posX-7, posY+5, posZ-5, posX-7, posY+8, posZ-5, Blocks.planks, 0, 3, true, true);
					WorldHelper.fillAreaWithBlock(posX-7, posY+5, posZ-6, posX-7, posY+8, posZ-6, Blocks.planks, 0, 3, true, true);
					WorldHelper.fillAreaWithBlock(posX-6, posY+5, posZ-7, posX-6, posY+8, posZ-7, Blocks.planks, 0, 3, true, true);
					WorldHelper.fillAreaWithBlock(posX-5, posY+5, posZ-8, posX-5, posY+8, posZ-8, Blocks.planks, 0, 3, true, true);
					WorldHelper.fillAreaWithBlock(posX-4, posY+5, posZ-9, posX-4, posY+8, posZ-9, Blocks.planks, 0, 3, true, true);
					WorldHelper.fillAreaWithBlock(posX-3, posY+5, posZ-10, posX-3, posY+8, posZ-10, Blocks.planks, 0, 3, true, true);
					WorldHelper.fillAreaWithBlock(posX-2, posY+5, posZ-11, posX-2, posY+8, posZ-11, Blocks.planks, 0, 3, true, true);
					WorldHelper.fillAreaWithBlock(posX-1, posY+5, posZ-12, posX-1, posY+8, posZ-12, Blocks.planks, 0, 3, true, true);
					WorldHelper.fillAreaWithBlock(posX, posY+5, posZ-13, posX+25, posY+8, posZ-13, Blocks.planks, 0, 3, true, true);**/
					world.setBlock(posX + 11, posY + 15, posZ + 24, Blocks.wool, 0, 3);
					world.setBlock(posX + 11, posY + 15, posZ + 25, Blocks.fence, 0, 3);
					world.setBlock(posX + 11, posY + 16, posZ + 23, Blocks.wool, 0, 3);
					world.setBlock(posX + 11, posY + 17, posZ + 23, Blocks.wool, 0, 3);
					world.setBlock(posX + 11, posY + 18, posZ + 24, Blocks.wool, 0, 3);
					world.setBlock(posX + 11, posY + 19, posZ + 25, Blocks.wool, 0, 3);
					world.setBlock(posX + 11, posY + 20, posZ + 25, Blocks.fence, 0, 3);
					world.setBlock(posX + 12, posY + 5, posZ + 20, Blocks.wooden_slab, 9, 3);
					world.setBlock(posX + 12, posY + 5, posZ + 23, Blocks.wooden_slab, 9, 3);
					world.setBlock(posX + 12, posY + 5, posZ + 33, Blocks.wooden_slab, 9, 3);
					world.setBlock(posX + 12, posY + 5, posZ + 36, Blocks.wooden_slab, 9, 3);
					world.setBlock(posX + 12, posY + 5, posZ + 39, Blocks.wooden_slab, 9, 3);
					world.setBlock(posX + 12, posY + 5, posZ + 42, Blocks.wooden_slab, 9, 3);
					world.setBlock(posX + 12, posY + 6, posZ + 12, Blocks.planks, 1, 3);
					world.setBlock(posX + 12, posY + 6, posZ + 13, Blocks.planks, 1, 3);
					world.setBlock(posX + 12, posY + 6, posZ + 14, Blocks.planks, 1, 3);
					world.setBlock(posX + 12, posY + 6, posZ + 15, Blocks.planks, 1, 3);
					world.setBlock(posX + 12, posY + 6, posZ + 16, Blocks.planks, 1, 3);
					world.setBlock(posX + 12, posY + 6, posZ + 17, Blocks.planks, 1, 3);
					world.setBlock(posX + 12, posY + 6, posZ + 18, Blocks.planks, 1, 3);
					world.setBlock(posX + 12, posY + 6, posZ + 19, Blocks.planks, 1, 3);
					world.setBlock(posX + 12, posY + 6, posZ + 20, Blocks.stained_hardened_clay, 15, 3);
					world.setBlock(posX + 12, posY + 6, posZ + 21, Blocks.planks, 1, 3);
					world.setBlock(posX + 12, posY + 6, posZ + 22, Blocks.planks, 1, 3);
					world.setBlock(posX + 12, posY + 6, posZ + 23, Blocks.stained_hardened_clay, 15, 3);
					world.setBlock(posX + 12, posY + 6, posZ + 24, Blocks.planks, 1, 3);
					world.setBlock(posX + 12, posY + 6, posZ + 25, Blocks.planks, 1, 3);
					world.setBlock(posX + 12, posY + 6, posZ + 26, Blocks.planks, 1, 3);
					world.setBlock(posX + 12, posY + 6, posZ + 27, Blocks.planks, 1, 3);
					world.setBlock(posX + 12, posY + 6, posZ + 28, Blocks.planks, 1, 3);
					world.setBlock(posX + 12, posY + 6, posZ + 29, Blocks.planks, 1, 3);
					world.setBlock(posX + 12, posY + 6, posZ + 30, Blocks.planks, 1, 3);
					world.setBlock(posX + 12, posY + 6, posZ + 31, Blocks.planks, 1, 3);
					world.setBlock(posX + 12, posY + 6, posZ + 32, Blocks.planks, 1, 3);
					world.setBlock(posX + 12, posY + 6, posZ + 33, Blocks.stained_hardened_clay, 15, 3);
					world.setBlock(posX + 12, posY + 6, posZ + 34, Blocks.planks, 1, 3);
					world.setBlock(posX + 12, posY + 6, posZ + 35, Blocks.planks, 1, 3);
					world.setBlock(posX + 12, posY + 6, posZ + 36, Blocks.stained_hardened_clay, 15, 3);
					world.setBlock(posX + 12, posY + 6, posZ + 37, Blocks.planks, 1, 3);
					world.setBlock(posX + 12, posY + 6, posZ + 38, Blocks.planks, 1, 3);
					world.setBlock(posX + 12, posY + 6, posZ + 39, Blocks.stained_hardened_clay, 15, 3);
					world.setBlock(posX + 12, posY + 6, posZ + 40, Blocks.planks, 1, 3);
					world.setBlock(posX + 12, posY + 6, posZ + 41, Blocks.planks, 1, 3);
					world.setBlock(posX + 12, posY + 6, posZ + 42, Blocks.stained_hardened_clay, 15, 3);
					world.setBlock(posX + 12, posY + 6, posZ + 43, Blocks.planks, 1, 3);
					world.setBlock(posX + 12, posY + 6, posZ + 44, Blocks.planks, 1, 3);
					world.setBlock(posX + 12, posY + 6, posZ + 45, Blocks.planks, 1, 3);
					world.setBlock(posX + 12, posY + 7, posZ + 11, Blocks.planks, 1, 3);
					world.setBlock(posX + 12, posY + 7, posZ + 12, Blocks.log, 1, 3);
					world.setBlock(posX + 12, posY + 7, posZ + 13, Blocks.glass_pane, 0, 3);
					world.setBlock(posX + 12, posY + 7, posZ + 14, Blocks.glass_pane, 0, 3);
					world.setBlock(posX + 12, posY + 7, posZ + 15, Blocks.log, 1, 3);
					world.setBlock(posX + 12, posY + 7, posZ + 16, Blocks.planks, 1, 3);
					world.setBlock(posX + 12, posY + 7, posZ + 17, Blocks.planks, 1, 3);
					world.setBlock(posX + 12, posY + 7, posZ + 18, Blocks.planks, 1, 3);
					world.setBlock(posX + 12, posY + 7, posZ + 19, Blocks.planks, 1, 3);
					world.setBlock(posX + 12, posY + 7, posZ + 20, Blocks.planks, 1, 3);
					world.setBlock(posX + 12, posY + 7, posZ + 21, Blocks.planks, 1, 3);
					world.setBlock(posX + 12, posY + 7, posZ + 22, Blocks.planks, 1, 3);
					world.setBlock(posX + 12, posY + 7, posZ + 23, Blocks.log, 1, 3);
					world.setBlock(posX + 12, posY + 7, posZ + 24, Blocks.glass_pane, 0, 3);
					world.setBlock(posX + 12, posY + 7, posZ + 25, Blocks.glass_pane, 0, 3);
					world.setBlock(posX + 12, posY + 7, posZ + 26, Blocks.log, 1, 3);
					world.setBlock(posX + 12, posY + 7, posZ + 27, Blocks.planks, 1, 3);
					world.setBlock(posX + 12, posY + 7, posZ + 28, Blocks.planks, 1, 3);
					world.setBlock(posX + 12, posY + 7, posZ + 29, Blocks.planks, 1, 3);
					world.setBlock(posX + 12, posY + 7, posZ + 30, Blocks.planks, 1, 3);
					world.setBlock(posX + 12, posY + 7, posZ + 31, Blocks.planks, 1, 3);
					world.setBlock(posX + 12, posY + 7, posZ + 32, Blocks.planks, 1, 3);
					world.setBlock(posX + 12, posY + 7, posZ + 33, Blocks.planks, 1, 3);
					world.setBlock(posX + 12, posY + 7, posZ + 34, Blocks.log, 1, 3);
					world.setBlock(posX + 12, posY + 7, posZ + 35, Blocks.glass_pane, 0, 3);
					world.setBlock(posX + 12, posY + 7, posZ + 36, Blocks.glass_pane, 0, 3);
					world.setBlock(posX + 12, posY + 7, posZ + 37, Blocks.log, 1, 3);
					world.setBlock(posX + 12, posY + 7, posZ + 38, Blocks.planks, 1, 3);
					world.setBlock(posX + 12, posY + 7, posZ + 39, Blocks.planks, 1, 3);
					world.setBlock(posX + 12, posY + 7, posZ + 40, Blocks.planks, 1, 3);
					world.setBlock(posX + 12, posY + 7, posZ + 41, Blocks.planks, 1, 3);
					world.setBlock(posX + 12, posY + 7, posZ + 42, Blocks.planks, 1, 3);
					world.setBlock(posX + 12, posY + 7, posZ + 43, Blocks.planks, 1, 3);
					world.setBlock(posX + 12, posY + 7, posZ + 44, Blocks.planks, 1, 3);
					world.setBlock(posX + 12, posY + 7, posZ + 45, Blocks.planks, 1, 3);
					world.setBlock(posX + 12, posY + 8, posZ + 12, Blocks.planks, 1, 3);
					world.setBlock(posX + 12, posY + 8, posZ + 13, Blocks.planks, 1, 3);
					world.setBlock(posX + 12, posY + 8, posZ + 14, Blocks.planks, 1, 3);
					world.setBlock(posX + 12, posY + 8, posZ + 15, Blocks.planks, 1, 3);
					world.setBlock(posX + 12, posY + 8, posZ + 16, Blocks.planks, 1, 3);
					world.setBlock(posX + 12, posY + 8, posZ + 17, Blocks.planks, 1, 3);
					world.setBlock(posX + 12, posY + 8, posZ + 18, Blocks.planks, 1, 3);
					world.setBlock(posX + 12, posY + 8, posZ + 19, Blocks.planks, 1, 3);
					world.setBlock(posX + 12, posY + 8, posZ + 20, Blocks.planks, 1, 3);
					world.setBlock(posX + 12, posY + 8, posZ + 21, Blocks.planks, 1, 3);
					world.setBlock(posX + 12, posY + 8, posZ + 22, Blocks.planks, 1, 3);
					world.setBlock(posX + 12, posY + 8, posZ + 23, Blocks.planks, 1, 3);
					world.setBlock(posX + 12, posY + 8, posZ + 24, Blocks.planks, 1, 3);
					world.setBlock(posX + 12, posY + 8, posZ + 25, Blocks.planks, 1, 3);
					world.setBlock(posX + 12, posY + 8, posZ + 26, Blocks.planks, 1, 3);
					world.setBlock(posX + 12, posY + 8, posZ + 27, Blocks.planks, 1, 3);
					world.setBlock(posX + 12, posY + 8, posZ + 28, Blocks.planks, 1, 3);
					world.setBlock(posX + 12, posY + 8, posZ + 29, Blocks.planks, 1, 3);
					world.setBlock(posX + 12, posY + 8, posZ + 30, Blocks.planks, 1, 3);
					world.setBlock(posX + 12, posY + 8, posZ + 31, Blocks.planks, 1, 3);
					world.setBlock(posX + 12, posY + 8, posZ + 32, Blocks.planks, 1, 3);
					world.setBlock(posX + 12, posY + 8, posZ + 33, Blocks.planks, 1, 3);
					world.setBlock(posX + 12, posY + 8, posZ + 34, Blocks.planks, 1, 3);
					world.setBlock(posX + 12, posY + 8, posZ + 35, Blocks.planks, 1, 3);
					world.setBlock(posX + 12, posY + 8, posZ + 36, Blocks.planks, 1, 3);
					world.setBlock(posX + 12, posY + 8, posZ + 37, Blocks.planks, 1, 3);
					world.setBlock(posX + 12, posY + 8, posZ + 38, Blocks.planks, 1, 3);
					world.setBlock(posX + 12, posY + 8, posZ + 39, Blocks.planks, 1, 3);
					world.setBlock(posX + 12, posY + 8, posZ + 40, Blocks.planks, 1, 3);
					world.setBlock(posX + 12, posY + 8, posZ + 41, Blocks.planks, 1, 3);
					world.setBlock(posX + 12, posY + 8, posZ + 42, Blocks.planks, 1, 3);
					world.setBlock(posX + 12, posY + 8, posZ + 43, Blocks.planks, 1, 3);
					world.setBlock(posX + 12, posY + 8, posZ + 44, Blocks.planks, 1, 3);
					world.setBlock(posX + 12, posY + 8, posZ + 45, Blocks.planks, 1, 3);
					world.setBlock(posX + 12, posY + 9, posZ + 12, Blocks.planks, 1, 3);
					world.setBlock(posX + 12, posY + 9, posZ + 13, Blocks.planks, 1, 3);
					world.setBlock(posX + 12, posY + 9, posZ + 14, Blocks.planks, 1, 3);
					world.setBlock(posX + 12, posY + 9, posZ + 15, Blocks.planks, 1, 3);
					world.setBlock(posX + 12, posY + 9, posZ + 16, Blocks.planks, 1, 3);
					world.setBlock(posX + 12, posY + 9, posZ + 17, Blocks.planks, 1, 3);
					world.setBlock(posX + 12, posY + 9, posZ + 18, Blocks.planks, 1, 3);
					world.setBlock(posX + 12, posY + 9, posZ + 19, Blocks.planks, 1, 3);
					world.setBlock(posX + 12, posY + 9, posZ + 20, Blocks.planks, 1, 3);
					world.setBlock(posX + 12, posY + 9, posZ + 21, Blocks.planks, 1, 3);
					world.setBlock(posX + 12, posY + 9, posZ + 22, Blocks.planks, 1, 3);
					world.setBlock(posX + 12, posY + 9, posZ + 23, Blocks.planks, 1, 3);
					world.setBlock(posX + 12, posY + 9, posZ + 24, Blocks.planks, 1, 3);
					world.setBlock(posX + 12, posY + 9, posZ + 25, Blocks.planks, 1, 3);
					world.setBlock(posX + 12, posY + 9, posZ + 26, Blocks.planks, 1, 3);
					world.setBlock(posX + 12, posY + 9, posZ + 27, Blocks.planks, 1, 3);
					world.setBlock(posX + 12, posY + 9, posZ + 28, Blocks.planks, 1, 3);
					world.setBlock(posX + 12, posY + 9, posZ + 29, Blocks.planks, 1, 3);
					world.setBlock(posX + 12, posY + 9, posZ + 30, Blocks.planks, 1, 3);
					world.setBlock(posX + 12, posY + 9, posZ + 31, Blocks.planks, 1, 3);
					world.setBlock(posX + 12, posY + 9, posZ + 32, Blocks.planks, 1, 3);
					world.setBlock(posX + 12, posY + 9, posZ + 33, Blocks.planks, 1, 3);
					world.setBlock(posX + 12, posY + 9, posZ + 34, Blocks.planks, 1, 3);
					world.setBlock(posX + 12, posY + 9, posZ + 35, Blocks.planks, 1, 3);
					world.setBlock(posX + 12, posY + 9, posZ + 36, Blocks.planks, 1, 3);
					world.setBlock(posX + 12, posY + 9, posZ + 37, Blocks.planks, 1, 3);
					world.setBlock(posX + 12, posY + 9, posZ + 38, Blocks.planks, 1, 3);
					world.setBlock(posX + 12, posY + 9, posZ + 39, Blocks.planks, 1, 3);
					world.setBlock(posX + 12, posY + 9, posZ + 40, Blocks.planks, 1, 3);
					world.setBlock(posX + 12, posY + 9, posZ + 41, Blocks.planks, 1, 3);
					world.setBlock(posX + 12, posY + 9, posZ + 42, Blocks.planks, 1, 3);
					world.setBlock(posX + 12, posY + 9, posZ + 43, Blocks.planks, 1, 3);
					world.setBlock(posX + 12, posY + 9, posZ + 44, Blocks.planks, 1, 3);
					world.setBlock(posX + 12, posY + 9, posZ + 45, Blocks.planks, 1, 3);
					world.setBlock(posX + 12, posY + 10, posZ + 12, Blocks.log, 1, 3);
					world.setBlock(posX + 12, posY + 10, posZ + 13, Blocks.log, 1, 3);
					world.setBlock(posX + 12, posY + 10, posZ + 14, Blocks.log, 1, 3);
					world.setBlock(posX + 12, posY + 10, posZ + 15, Blocks.log, 1, 3);
					world.setBlock(posX + 12, posY + 10, posZ + 16, Blocks.log, 1, 3);
					world.setBlock(posX + 12, posY + 10, posZ + 17, Blocks.log, 1, 3);
					world.setBlock(posX + 12, posY + 10, posZ + 18, Blocks.log, 1, 3);
					world.setBlock(posX + 12, posY + 10, posZ + 19, Blocks.log, 1, 3);
					world.setBlock(posX + 12, posY + 10, posZ + 20, Blocks.log, 1, 3);
					world.setBlock(posX + 12, posY + 10, posZ + 21, Blocks.log, 1, 3);
					world.setBlock(posX + 12, posY + 10, posZ + 22, Blocks.log, 1, 3);
					world.setBlock(posX + 12, posY + 10, posZ + 23, Blocks.log, 1, 3);
					world.setBlock(posX + 12, posY + 10, posZ + 24, Blocks.log, 1, 3);
					world.setBlock(posX + 12, posY + 10, posZ + 25, Blocks.log, 1, 3);
					world.setBlock(posX + 12, posY + 10, posZ + 26, Blocks.log, 1, 3);
					world.setBlock(posX + 12, posY + 10, posZ + 27, Blocks.log, 1, 3);
					world.setBlock(posX + 12, posY + 10, posZ + 28, Blocks.log, 1, 3);
					world.setBlock(posX + 12, posY + 10, posZ + 29, Blocks.log, 1, 3);
					world.setBlock(posX + 12, posY + 10, posZ + 30, Blocks.log, 1, 3);
					world.setBlock(posX + 12, posY + 10, posZ + 31, Blocks.log, 1, 3);
					world.setBlock(posX + 12, posY + 10, posZ + 32, Blocks.log, 1, 3);
					world.setBlock(posX + 12, posY + 10, posZ + 33, Blocks.log, 1, 3);
					world.setBlock(posX + 12, posY + 10, posZ + 34, Blocks.log, 1, 3);
					world.setBlock(posX + 12, posY + 10, posZ + 35, Blocks.log, 1, 3);
					world.setBlock(posX + 12, posY + 10, posZ + 36, Blocks.log, 1, 3);
					world.setBlock(posX + 12, posY + 10, posZ + 37, Blocks.log, 1, 3);
					world.setBlock(posX + 12, posY + 10, posZ + 38, Blocks.log, 1, 3);
					world.setBlock(posX + 12, posY + 10, posZ + 39, Blocks.log, 1, 3);
					world.setBlock(posX + 12, posY + 10, posZ + 40, Blocks.planks, 1, 3);
					world.setBlock(posX + 12, posY + 10, posZ + 41, Blocks.planks, 1, 3);
					world.setBlock(posX + 12, posY + 10, posZ + 42, Blocks.planks, 1, 3);
					world.setBlock(posX + 12, posY + 10, posZ + 43, Blocks.planks, 1, 3);
					world.setBlock(posX + 12, posY + 10, posZ + 44, Blocks.planks, 1, 3);
					world.setBlock(posX + 12, posY + 10, posZ + 45, Blocks.log, 1, 3);
					world.setBlock(posX + 12, posY + 11, posZ + 12, Blocks.fence, 0, 3);
					world.setBlock(posX + 12, posY + 11, posZ + 13, Blocks.fence, 0, 3);
					world.setBlock(posX + 12, posY + 11, posZ + 14, Blocks.fence, 0, 3);
					world.setBlock(posX + 12, posY + 11, posZ + 15, Blocks.fence, 0, 3);
					world.setBlock(posX + 12, posY + 11, posZ + 16, Blocks.fence, 0, 3);
					world.setBlock(posX + 12, posY + 11, posZ + 17, Blocks.fence, 0, 3);
					world.setBlock(posX + 12, posY + 11, posZ + 18, Blocks.fence, 0, 3);
					world.setBlock(posX + 12, posY + 11, posZ + 19, Blocks.fence, 0, 3);
					world.setBlock(posX + 12, posY + 11, posZ + 20, Blocks.fence, 0, 3);
					world.setBlock(posX + 12, posY + 11, posZ + 21, Blocks.fence, 0, 3);
					world.setBlock(posX + 12, posY + 11, posZ + 22, Blocks.fence, 0, 3);
					world.setBlock(posX + 12, posY + 11, posZ + 23, Blocks.fence, 0, 3);
					world.setBlock(posX + 12, posY + 11, posZ + 24, Blocks.fence, 0, 3);
					world.setBlock(posX + 12, posY + 11, posZ + 25, Blocks.fence, 0, 3);
					world.setBlock(posX + 12, posY + 11, posZ + 26, Blocks.fence, 0, 3);
					world.setBlock(posX + 12, posY + 11, posZ + 27, Blocks.fence, 0, 3);
					world.setBlock(posX + 12, posY + 11, posZ + 28, Blocks.fence, 0, 3);
					world.setBlock(posX + 12, posY + 11, posZ + 29, Blocks.fence, 0, 3);
					world.setBlock(posX + 12, posY + 11, posZ + 30, Blocks.fence, 0, 3);
					world.setBlock(posX + 12, posY + 11, posZ + 31, Blocks.fence, 0, 3);
					world.setBlock(posX + 12, posY + 11, posZ + 32, Blocks.fence, 0, 3);
					world.setBlock(posX + 12, posY + 11, posZ + 33, Blocks.fence, 0, 3);
					world.setBlock(posX + 12, posY + 11, posZ + 34, Blocks.fence, 0, 3);
					world.setBlock(posX + 12, posY + 11, posZ + 35, Blocks.fence, 0, 3);
					world.setBlock(posX + 12, posY + 11, posZ + 36, Blocks.fence, 0, 3);
					world.setBlock(posX + 12, posY + 11, posZ + 37, Blocks.fence, 0, 3);
					world.setBlock(posX + 12, posY + 11, posZ + 38, Blocks.fence, 0, 3);
					world.setBlock(posX + 12, posY + 11, posZ + 39, Blocks.log, 1, 3);
					world.setBlock(posX + 12, posY + 11, posZ + 40, Blocks.planks, 1, 3);
					world.setBlock(posX + 12, posY + 11, posZ + 41, Blocks.planks, 1, 3);
					world.setBlock(posX + 12, posY + 11, posZ + 42, Blocks.planks, 1, 3);
					world.setBlock(posX + 12, posY + 11, posZ + 43, Blocks.planks, 1, 3);
					world.setBlock(posX + 12, posY + 11, posZ + 44, Blocks.planks, 1, 3);
					world.setBlock(posX + 12, posY + 11, posZ + 45, Blocks.log, 1, 3);
					world.setBlock(posX + 12, posY + 12, posZ + 18, Blocks.stained_hardened_clay, 15, 3);
					world.setBlock(posX + 12, posY + 12, posZ + 24, Blocks.stained_hardened_clay, 15, 3);
					world.setBlock(posX + 12, posY + 12, posZ + 30, Blocks.stained_hardened_clay, 15, 3);
					world.setBlock(posX + 12, posY + 12, posZ + 36, Blocks.stained_hardened_clay, 15, 3);
					world.setBlock(posX + 12, posY + 12, posZ + 38, Blocks.fence, 0, 3);
					world.setBlock(posX + 12, posY + 12, posZ + 39, Blocks.log, 1, 3);
					world.setBlock(posX + 12, posY + 12, posZ + 40, Blocks.planks, 1, 3);
					world.setBlock(posX + 12, posY + 12, posZ + 41, Blocks.planks, 1, 3);
					world.setBlock(posX + 12, posY + 12, posZ + 42, Blocks.planks, 1, 3);
					world.setBlock(posX + 12, posY + 12, posZ + 43, Blocks.planks, 1, 3);
					world.setBlock(posX + 12, posY + 12, posZ + 44, Blocks.planks, 1, 3);
					world.setBlock(posX + 12, posY + 12, posZ + 45, Blocks.log, 1, 3);
					world.setBlock(posX + 12, posY + 13, posZ + 39, Blocks.log, 1, 3);
					world.setBlock(posX + 12, posY + 13, posZ + 40, Blocks.planks, 1, 3);
					world.setBlock(posX + 12, posY + 13, posZ + 41, Blocks.planks, 1, 3);
					world.setBlock(posX + 12, posY + 13, posZ + 42, Blocks.planks, 1, 3);
					world.setBlock(posX + 12, posY + 13, posZ + 43, Blocks.planks, 1, 3);
					world.setBlock(posX + 12, posY + 13, posZ + 44, Blocks.planks, 1, 3);
					world.setBlock(posX + 12, posY + 13, posZ + 45, Blocks.log, 1, 3);
					world.setBlock(posX + 12, posY + 14, posZ + 39, Blocks.log, 1, 3);
					world.setBlock(posX + 12, posY + 14, posZ + 40, Blocks.planks, 1, 3);
					world.setBlock(posX + 12, posY + 14, posZ + 41, Blocks.planks, 1, 3);
					world.setBlock(posX + 12, posY + 14, posZ + 42, Blocks.planks, 1, 3);
					world.setBlock(posX + 12, posY + 14, posZ + 43, Blocks.planks, 1, 3);
					world.setBlock(posX + 12, posY + 14, posZ + 44, Blocks.planks, 1, 3);
					world.setBlock(posX + 12, posY + 14, posZ + 45, Blocks.log, 1, 3);
					world.setBlock(posX + 12, posY + 15, posZ + 24, Blocks.wool, 0, 3);
					world.setBlock(posX + 12, posY + 15, posZ + 25, Blocks.fence, 0, 3);
					world.setBlock(posX + 12, posY + 15, posZ + 39, Blocks.fence, 0, 3);
					world.setBlock(posX + 12, posY + 15, posZ + 40, Blocks.fence, 0, 3);
					world.setBlock(posX + 12, posY + 15, posZ + 41, Blocks.fence, 0, 3);
					world.setBlock(posX + 12, posY + 15, posZ + 42, Blocks.fence, 0, 3);
					world.setBlock(posX + 12, posY + 15, posZ + 43, Blocks.fence, 0, 3);
					world.setBlock(posX + 12, posY + 15, posZ + 44, Blocks.fence, 0, 3);
					world.setBlock(posX + 12, posY + 15, posZ + 45, Blocks.fence, 0, 3);
					world.setBlock(posX + 12, posY + 16, posZ + 23, Blocks.wool, 0, 3);
					world.setBlock(posX + 12, posY + 17, posZ + 23, Blocks.wool, 0, 3);
					world.setBlock(posX + 12, posY + 18, posZ + 24, Blocks.wool, 0, 3);
					world.setBlock(posX + 12, posY + 19, posZ + 25, Blocks.wool, 0, 3);
					world.setBlock(posX + 12, posY + 20, posZ + 25, Blocks.fence, 0, 3);
					world.setBlock(posX + 13, posY + 4, posZ + 13, Blocks.planks, 1, 3);
					world.setBlock(posX + 13, posY + 4, posZ + 14, Blocks.planks, 1, 3);
					world.setBlock(posX + 13, posY + 4, posZ + 15, Blocks.planks, 1, 3);
					world.setBlock(posX + 13, posY + 4, posZ + 16, Blocks.planks, 1, 3);
					world.setBlock(posX + 13, posY + 4, posZ + 17, Blocks.planks, 1, 3);
					world.setBlock(posX + 13, posY + 4, posZ + 18, Blocks.planks, 1, 3);
					world.setBlock(posX + 13, posY + 4, posZ + 19, Blocks.planks, 1, 3);
					world.setBlock(posX + 13, posY + 4, posZ + 20, Blocks.planks, 1, 3);
					world.setBlock(posX + 13, posY + 4, posZ + 21, Blocks.planks, 1, 3);
					world.setBlock(posX + 13, posY + 4, posZ + 22, Blocks.planks, 1, 3);
					world.setBlock(posX + 13, posY + 4, posZ + 23, Blocks.planks, 1, 3);
					world.setBlock(posX + 13, posY + 4, posZ + 24, Blocks.planks, 1, 3);
					world.setBlock(posX + 13, posY + 4, posZ + 25, Blocks.planks, 1, 3);
					world.setBlock(posX + 13, posY + 4, posZ + 26, Blocks.planks, 1, 3);
					world.setBlock(posX + 13, posY + 4, posZ + 27, Blocks.planks, 1, 3);
					world.setBlock(posX + 13, posY + 4, posZ + 28, Blocks.planks, 1, 3);
					world.setBlock(posX + 13, posY + 4, posZ + 29, Blocks.planks, 1, 3);
					world.setBlock(posX + 13, posY + 4, posZ + 30, Blocks.planks, 1, 3);
					world.setBlock(posX + 13, posY + 4, posZ + 31, Blocks.planks, 1, 3);
					world.setBlock(posX + 13, posY + 4, posZ + 32, Blocks.planks, 1, 3);
					world.setBlock(posX + 13, posY + 4, posZ + 33, Blocks.planks, 1, 3);
					world.setBlock(posX + 13, posY + 4, posZ + 34, Blocks.planks, 1, 3);
					world.setBlock(posX + 13, posY + 4, posZ + 35, Blocks.planks, 1, 3);
					world.setBlock(posX + 13, posY + 4, posZ + 36, Blocks.planks, 1, 3);
					world.setBlock(posX + 13, posY + 4, posZ + 37, Blocks.planks, 1, 3);
					world.setBlock(posX + 13, posY + 4, posZ + 38, Blocks.planks, 1, 3);
					world.setBlock(posX + 13, posY + 4, posZ + 39, Blocks.planks, 1, 3);
					world.setBlock(posX + 13, posY + 4, posZ + 40, Blocks.planks, 1, 3);
					world.setBlock(posX + 13, posY + 4, posZ + 41, Blocks.planks, 1, 3);
					world.setBlock(posX + 13, posY + 4, posZ + 42, Blocks.planks, 1, 3);
					world.setBlock(posX + 13, posY + 4, posZ + 43, Blocks.planks, 1, 3);
					world.setBlock(posX + 13, posY + 4, posZ + 44, Blocks.planks, 1, 3);
					world.setBlock(posX + 13, posY + 5, posZ + 12, Blocks.planks, 1, 3);
					world.setBlock(posX + 13, posY + 5, posZ + 13, Blocks.planks, 1, 3);
					world.setBlock(posX + 13, posY + 5, posZ + 14, Blocks.planks, 1, 3);
					world.setBlock(posX + 13, posY + 5, posZ + 15, Blocks.planks, 1, 3);
					world.setBlock(posX + 13, posY + 5, posZ + 16, Blocks.planks, 1, 3);
					world.setBlock(posX + 13, posY + 5, posZ + 17, Blocks.planks, 1, 3);
					world.setBlock(posX + 13, posY + 5, posZ + 18, Blocks.planks, 1, 3);
					world.setBlock(posX + 13, posY + 5, posZ + 19, Blocks.planks, 1, 3);
					world.setBlock(posX + 13, posY + 5, posZ + 20, Blocks.planks, 1, 3);
					world.setBlock(posX + 13, posY + 5, posZ + 21, Blocks.planks, 1, 3);
					world.setBlock(posX + 13, posY + 5, posZ + 22, Blocks.planks, 1, 3);
					world.setBlock(posX + 13, posY + 5, posZ + 23, Blocks.planks, 1, 3);
					world.setBlock(posX + 13, posY + 5, posZ + 24, Blocks.planks, 1, 3);
					world.setBlock(posX + 13, posY + 5, posZ + 25, Blocks.planks, 1, 3);
					world.setBlock(posX + 13, posY + 5, posZ + 26, Blocks.planks, 1, 3);
					world.setBlock(posX + 13, posY + 5, posZ + 27, Blocks.planks, 1, 3);
					world.setBlock(posX + 13, posY + 5, posZ + 28, Blocks.planks, 1, 3);
					world.setBlock(posX + 13, posY + 5, posZ + 29, Blocks.planks, 1, 3);
					world.setBlock(posX + 13, posY + 5, posZ + 30, Blocks.planks, 1, 3);
					world.setBlock(posX + 13, posY + 5, posZ + 31, Blocks.planks, 1, 3);
					world.setBlock(posX + 13, posY + 5, posZ + 32, Blocks.planks, 1, 3);
					world.setBlock(posX + 13, posY + 5, posZ + 33, Blocks.planks, 1, 3);
					world.setBlock(posX + 13, posY + 5, posZ + 34, Blocks.planks, 1, 3);
					world.setBlock(posX + 13, posY + 5, posZ + 35, Blocks.planks, 1, 3);
					world.setBlock(posX + 13, posY + 5, posZ + 36, Blocks.planks, 1, 3);
					world.setBlock(posX + 13, posY + 5, posZ + 37, Blocks.planks, 1, 3);
					world.setBlock(posX + 13, posY + 5, posZ + 38, Blocks.planks, 1, 3);
					world.setBlock(posX + 13, posY + 5, posZ + 39, Blocks.planks, 1, 3);
					world.setBlock(posX + 13, posY + 5, posZ + 40, Blocks.planks, 1, 3);
					world.setBlock(posX + 13, posY + 5, posZ + 41, Blocks.planks, 1, 3);
					world.setBlock(posX + 13, posY + 5, posZ + 42, Blocks.planks, 1, 3);
					world.setBlock(posX + 13, posY + 5, posZ + 43, Blocks.planks, 1, 3);
					world.setBlock(posX + 13, posY + 5, posZ + 44, Blocks.planks, 1, 3);
					world.setBlock(posX + 13, posY + 6, posZ + 11, Blocks.planks, 1, 3);
					world.setBlock(posX + 13, posY + 6, posZ + 16, Blocks.log, 1, 3);
					world.setBlock(posX + 13, posY + 6, posZ + 27, Blocks.log, 1, 3);
					world.setBlock(posX + 13, posY + 6, posZ + 28, Blocks.fence, 0, 3);
					world.setBlock(posX + 13, posY + 6, posZ + 33, Blocks.stained_hardened_clay, 15, 3);
					world.setBlock(posX + 13, posY + 6, posZ + 36, Blocks.stained_hardened_clay, 15, 3);
					world.setBlock(posX + 13, posY + 6, posZ + 39, Blocks.stained_hardened_clay, 15, 3);
					world.setBlock(posX + 13, posY + 6, posZ + 42, Blocks.stained_hardened_clay, 15, 3);
					world.setBlock(posX + 13, posY + 6, posZ + 45, Blocks.planks, 1, 3);
					world.setBlock(posX + 13, posY + 6, posZ + 46, Blocks.planks, 1, 3);
					world.setBlock(posX + 13, posY + 7, posZ + 10, Blocks.planks, 1, 3);
					world.setBlock(posX + 13, posY + 7, posZ + 11, Blocks.planks, 1, 3);
					world.setBlock(posX + 13, posY + 7, posZ + 16, Blocks.log, 1, 3);
					world.setBlock(posX + 13, posY + 7, posZ + 27, Blocks.planks, 1, 3);
					world.setBlock(posX + 13, posY + 7, posZ + 46, Blocks.planks, 1, 3);
					world.setBlock(posX + 13, posY + 8, posZ + 10, Blocks.planks, 1, 3);
					world.setBlock(posX + 13, posY + 8, posZ + 11, Blocks.planks, 1, 3);
					world.setBlock(posX + 13, posY + 8, posZ + 16, Blocks.log, 1, 3);
					world.setBlock(posX + 13, posY + 8, posZ + 27, Blocks.planks, 1, 3);
					world.setBlock(posX + 13, posY + 8, posZ + 46, Blocks.planks, 1, 3);
					world.setBlock(posX + 13, posY + 9, posZ + 10, Blocks.log, 8, 3);
					world.setBlock(posX + 13, posY + 9, posZ + 11, Blocks.planks, 1, 3);
					world.setBlock(posX + 13, posY + 9, posZ + 12, Blocks.planks, 1, 3);
					world.setBlock(posX + 13, posY + 9, posZ + 15, Blocks.wooden_slab, 9, 3);
					world.setBlock(posX + 13, posY + 9, posZ + 16, Blocks.iron_bars, 0, 3);
					world.setBlock(posX + 13, posY + 9, posZ + 27, Blocks.planks, 1, 3);
					world.setBlock(posX + 13, posY + 9, posZ + 29, Blocks.log, 1, 3);
					world.setBlock(posX + 13, posY + 9, posZ + 43, Blocks.log, 1, 3);
					world.setBlock(posX + 13, posY + 9, posZ + 45, Blocks.planks, 1, 3);
					world.setBlock(posX + 13, posY + 9, posZ + 46, Blocks.planks, 1, 3);
					world.setBlock(posX + 13, posY + 10, posZ + 11, Blocks.log, 1, 3);
					world.setBlock(posX + 13, posY + 10, posZ + 12, Blocks.log, 1, 3);
					world.setBlock(posX + 13, posY + 10, posZ + 13, Blocks.planks, 1, 3);
					world.setBlock(posX + 13, posY + 10, posZ + 14, Blocks.planks, 1, 3);
					world.setBlock(posX + 13, posY + 10, posZ + 15, Blocks.planks, 1, 3);
					world.setBlock(posX + 13, posY + 10, posZ + 16, Blocks.planks, 1, 3);
					world.setBlock(posX + 13, posY + 10, posZ + 17, Blocks.planks, 1, 3);
					world.setBlock(posX + 13, posY + 10, posZ + 18, Blocks.planks, 1, 3);
					world.setBlock(posX + 13, posY + 10, posZ + 19, Blocks.planks, 1, 3);
					world.setBlock(posX + 13, posY + 10, posZ + 20, Blocks.planks, 1, 3);
					world.setBlock(posX + 13, posY + 10, posZ + 21, Blocks.planks, 1, 3);
					world.setBlock(posX + 13, posY + 10, posZ + 22, Blocks.planks, 1, 3);
					world.setBlock(posX + 13, posY + 10, posZ + 23, Blocks.planks, 1, 3);
					world.setBlock(posX + 13, posY + 10, posZ + 24, Blocks.planks, 1, 3);
					world.setBlock(posX + 13, posY + 10, posZ + 25, Blocks.planks, 1, 3);
					world.setBlock(posX + 13, posY + 10, posZ + 26, Blocks.planks, 1, 3);
					world.setBlock(posX + 13, posY + 10, posZ + 27, Blocks.planks, 1, 3);
					world.setBlock(posX + 13, posY + 10, posZ + 28, Blocks.planks, 1, 3);
					world.setBlock(posX + 13, posY + 10, posZ + 29, Blocks.planks, 1, 3);
					world.setBlock(posX + 13, posY + 10, posZ + 30, Blocks.planks, 1, 3);
					world.setBlock(posX + 13, posY + 10, posZ + 31, Blocks.planks, 1, 3);
					world.setBlock(posX + 13, posY + 10, posZ + 32, Blocks.planks, 1, 3);
					world.setBlock(posX + 13, posY + 10, posZ + 33, Blocks.planks, 1, 3);
					world.setBlock(posX + 13, posY + 10, posZ + 34, Blocks.planks, 1, 3);
					world.setBlock(posX + 13, posY + 10, posZ + 35, Blocks.planks, 1, 3);
					world.setBlock(posX + 13, posY + 10, posZ + 36, Blocks.planks, 1, 3);
					world.setBlock(posX + 13, posY + 10, posZ + 37, Blocks.planks, 1, 3);
					world.setBlock(posX + 13, posY + 10, posZ + 38, Blocks.planks, 1, 3);
					world.setBlock(posX + 13, posY + 10, posZ + 39, Blocks.planks, 1, 3);
					world.setBlock(posX + 13, posY + 10, posZ + 40, Blocks.planks, 1, 3);
					world.setBlock(posX + 13, posY + 10, posZ + 41, Blocks.planks, 1, 3);
					world.setBlock(posX + 13, posY + 10, posZ + 42, Blocks.planks, 1, 3);
					world.setBlock(posX + 13, posY + 10, posZ + 43, Blocks.planks, 1, 3);
					world.setBlock(posX + 13, posY + 10, posZ + 44, Blocks.planks, 1, 3);
					world.setBlock(posX + 13, posY + 10, posZ + 45, Blocks.log, 1, 3);
					world.setBlock(posX + 13, posY + 10, posZ + 46, Blocks.planks, 1, 3);
					world.setBlock(posX + 13, posY + 11, posZ + 11, Blocks.fence, 0, 3);
					world.setBlock(posX + 13, posY + 11, posZ + 12, Blocks.fence, 0, 3);
					world.setBlock(posX + 13, posY + 11, posZ + 17, Blocks.oak_stairs, 4, 3);
					world.setBlock(posX + 13, posY + 11, posZ + 19, Blocks.oak_stairs, 4, 3);
					world.setBlock(posX + 13, posY + 11, posZ + 23, Blocks.oak_stairs, 4, 3);
					world.setBlock(posX + 13, posY + 11, posZ + 25, Blocks.oak_stairs, 4, 3);
					world.setBlock(posX + 13, posY + 11, posZ + 29, Blocks.oak_stairs, 4, 3);
					world.setBlock(posX + 13, posY + 11, posZ + 31, Blocks.oak_stairs, 4, 3);
					world.setBlock(posX + 13, posY + 11, posZ + 35, Blocks.oak_stairs, 4, 3);
					world.setBlock(posX + 13, posY + 11, posZ + 37, Blocks.oak_stairs, 4, 3);
					world.setBlock(posX + 13, posY + 11, posZ + 39, Blocks.planks, 1, 3);
					world.setBlock(posX + 13, posY + 11, posZ + 46, Blocks.planks, 1, 3);
					world.setBlock(posX + 13, posY + 12, posZ + 17, Blocks.oak_stairs, 0, 3);
					world.setBlock(posX + 13, posY + 12, posZ + 18, Blocks.stained_hardened_clay, 15, 3);
					world.setBlock(posX + 13, posY + 12, posZ + 19, Blocks.oak_stairs, 0, 3);
					world.setBlock(posX + 13, posY + 12, posZ + 23, Blocks.oak_stairs, 0, 3);
					world.setBlock(posX + 13, posY + 12, posZ + 24, Blocks.stained_hardened_clay, 15, 3);
					world.setBlock(posX + 13, posY + 12, posZ + 25, Blocks.oak_stairs, 0, 3);
					world.setBlock(posX + 13, posY + 12, posZ + 29, Blocks.oak_stairs, 0, 3);
					world.setBlock(posX + 13, posY + 12, posZ + 30, Blocks.stained_hardened_clay, 15, 3);
					world.setBlock(posX + 13, posY + 12, posZ + 31, Blocks.oak_stairs, 0, 3);
					world.setBlock(posX + 13, posY + 12, posZ + 35, Blocks.oak_stairs, 0, 3);
					world.setBlock(posX + 13, posY + 12, posZ + 36, Blocks.stained_hardened_clay, 15, 3);
					world.setBlock(posX + 13, posY + 12, posZ + 37, Blocks.oak_stairs, 0, 3);
					world.setBlock(posX + 13, posY + 12, posZ + 39, Blocks.planks, 1, 3);
					world.setBlock(posX + 13, posY + 12, posZ + 46, Blocks.planks, 1, 3);
					world.setBlock(posX + 13, posY + 13, posZ + 39, Blocks.planks, 1, 3);
					world.setBlock(posX + 13, posY + 13, posZ + 46, Blocks.planks, 1, 3);
					world.setBlock(posX + 13, posY + 14, posZ + 39, Blocks.planks, 1, 3);
					world.setBlock(posX + 13, posY + 14, posZ + 40, Blocks.planks, 1, 3);
					world.setBlock(posX + 13, posY + 14, posZ + 41, Blocks.planks, 1, 3);
					world.setBlock(posX + 13, posY + 14, posZ + 42, Blocks.planks, 1, 3);
					world.setBlock(posX + 13, posY + 14, posZ + 43, Blocks.planks, 1, 3);
					world.setBlock(posX + 13, posY + 14, posZ + 44, Blocks.planks, 1, 3);
					world.setBlock(posX + 13, posY + 14, posZ + 45, Blocks.planks, 1, 3);
					world.setBlock(posX + 13, posY + 14, posZ + 46, Blocks.planks, 1, 3);
					world.setBlock(posX + 13, posY + 15, posZ + 24, Blocks.wool, 0, 3);
					world.setBlock(posX + 13, posY + 15, posZ + 25, Blocks.fence, 0, 3);
					world.setBlock(posX + 13, posY + 15, posZ + 39, Blocks.fence, 0, 3);
					world.setBlock(posX + 13, posY + 15, posZ + 45, Blocks.fence, 0, 3);
					world.setBlock(posX + 13, posY + 15, posZ + 46, Blocks.fence, 0, 3);
					world.setBlock(posX + 13, posY + 16, posZ + 23, Blocks.wool, 0, 3);
					world.setBlock(posX + 13, posY + 17, posZ + 23, Blocks.wool, 0, 3);
					world.setBlock(posX + 13, posY + 18, posZ + 24, Blocks.wool, 0, 3);
					world.setBlock(posX + 13, posY + 19, posZ + 25, Blocks.wool, 0, 3);
					world.setBlock(posX + 13, posY + 20, posZ + 25, Blocks.fence, 0, 3);
					world.setBlock(posX + 14, posY + 3, posZ + 13, Blocks.planks, 1, 3);
					world.setBlock(posX + 14, posY + 3, posZ + 14, Blocks.planks, 1, 3);
					world.setBlock(posX + 14, posY + 3, posZ + 15, Blocks.planks, 1, 3);
					world.setBlock(posX + 14, posY + 3, posZ + 16, Blocks.planks, 1, 3);
					world.setBlock(posX + 14, posY + 3, posZ + 17, Blocks.planks, 1, 3);
					world.setBlock(posX + 14, posY + 3, posZ + 18, Blocks.planks, 1, 3);
					world.setBlock(posX + 14, posY + 3, posZ + 19, Blocks.planks, 1, 3);
					world.setBlock(posX + 14, posY + 3, posZ + 20, Blocks.planks, 1, 3);
					world.setBlock(posX + 14, posY + 3, posZ + 21, Blocks.planks, 1, 3);
					world.setBlock(posX + 14, posY + 3, posZ + 22, Blocks.planks, 1, 3);
					world.setBlock(posX + 14, posY + 3, posZ + 23, Blocks.planks, 1, 3);
					world.setBlock(posX + 14, posY + 3, posZ + 24, Blocks.planks, 1, 3);
					world.setBlock(posX + 14, posY + 3, posZ + 25, Blocks.planks, 1, 3);
					world.setBlock(posX + 14, posY + 3, posZ + 26, Blocks.planks, 1, 3);
					world.setBlock(posX + 14, posY + 3, posZ + 27, Blocks.planks, 1, 3);
					world.setBlock(posX + 14, posY + 3, posZ + 28, Blocks.planks, 1, 3);
					world.setBlock(posX + 14, posY + 3, posZ + 29, Blocks.planks, 1, 3);
					world.setBlock(posX + 14, posY + 3, posZ + 30, Blocks.planks, 1, 3);
					world.setBlock(posX + 14, posY + 3, posZ + 31, Blocks.planks, 1, 3);
					world.setBlock(posX + 14, posY + 3, posZ + 32, Blocks.planks, 1, 3);
					world.setBlock(posX + 14, posY + 3, posZ + 33, Blocks.planks, 1, 3);
					world.setBlock(posX + 14, posY + 3, posZ + 34, Blocks.planks, 1, 3);
					world.setBlock(posX + 14, posY + 3, posZ + 35, Blocks.planks, 1, 3);
					world.setBlock(posX + 14, posY + 3, posZ + 36, Blocks.planks, 1, 3);
					world.setBlock(posX + 14, posY + 3, posZ + 37, Blocks.planks, 1, 3);
					world.setBlock(posX + 14, posY + 3, posZ + 38, Blocks.planks, 1, 3);
					world.setBlock(posX + 14, posY + 3, posZ + 39, Blocks.planks, 1, 3);
					world.setBlock(posX + 14, posY + 3, posZ + 40, Blocks.planks, 1, 3);
					world.setBlock(posX + 14, posY + 3, posZ + 41, Blocks.planks, 1, 3);
					world.setBlock(posX + 14, posY + 3, posZ + 42, Blocks.planks, 1, 3);
					world.setBlock(posX + 14, posY + 3, posZ + 43, Blocks.planks, 1, 3);
					world.setBlock(posX + 14, posY + 3, posZ + 44, Blocks.planks, 1, 3);
					world.setBlock(posX + 14, posY + 4, posZ + 12, Blocks.planks, 1, 3);
					world.setBlock(posX + 14, posY + 4, posZ + 26, Blocks.planks, 1, 3);
					world.setBlock(posX + 14, posY + 4, posZ + 30, Blocks.planks, 1, 3);
					world.setBlock(posX + 14, posY + 4, posZ + 33, Blocks.mob_spawner, 5, 3);
					((TileEntityMobSpawner)world.getTileEntity(posX + 14, posY + 4, posZ + 33)).func_145881_a().setEntityName("Pirate");
					world.setBlock(posX + 14, posY + 4, posZ + 43, Blocks.chest, 5, 3);
					WeightedRandomChestContent.generateChestContents(world.rand, ModMisc.pirateChest.getItems(random), (TileEntityChest)world.getTileEntity(posX + 14, posY + 4, posZ + 43), ModMisc.pirateChest.getCount(random));
					world.setBlock(posX + 14, posY + 4, posZ + 44, Blocks.planks, 1, 3);
					world.setBlock(posX + 14, posY + 5, posZ + 11, Blocks.planks, 1, 3);
					world.setBlock(posX + 14, posY + 5, posZ + 12, Blocks.planks, 1, 3);
					world.setBlock(posX + 14, posY + 5, posZ + 13, Blocks.planks, 1, 3);
					world.setBlock(posX + 14, posY + 5, posZ + 14, Blocks.planks, 1, 3);
					world.setBlock(posX + 14, posY + 5, posZ + 15, Blocks.planks, 1, 3);
					world.setBlock(posX + 14, posY + 5, posZ + 16, Blocks.wooden_slab, 9, 3);
					world.setBlock(posX + 14, posY + 5, posZ + 17, Blocks.planks, 1, 3);
					world.setBlock(posX + 14, posY + 5, posZ + 18, Blocks.planks, 1, 3);
					world.setBlock(posX + 14, posY + 5, posZ + 19, Blocks.planks, 1, 3);
					world.setBlock(posX + 14, posY + 5, posZ + 20, Blocks.planks, 1, 3);
					world.setBlock(posX + 14, posY + 5, posZ + 21, Blocks.planks, 1, 3);
					world.setBlock(posX + 14, posY + 5, posZ + 22, Blocks.planks, 1, 3);
					world.setBlock(posX + 14, posY + 5, posZ + 23, Blocks.planks, 1, 3);
					world.setBlock(posX + 14, posY + 5, posZ + 24, Blocks.planks, 1, 3);
					world.setBlock(posX + 14, posY + 5, posZ + 25, Blocks.planks, 1, 3);
					world.setBlock(posX + 14, posY + 5, posZ + 26, Blocks.planks, 1, 3);
					world.setBlock(posX + 14, posY + 5, posZ + 27, Blocks.planks, 1, 3);
					world.setBlock(posX + 14, posY + 5, posZ + 28, Blocks.planks, 1, 3);
					world.setBlock(posX + 14, posY + 5, posZ + 29, Blocks.planks, 1, 3);
					world.setBlock(posX + 14, posY + 5, posZ + 30, Blocks.planks, 1, 3);
					world.setBlock(posX + 14, posY + 5, posZ + 31, Blocks.planks, 1, 3);
					world.setBlock(posX + 14, posY + 5, posZ + 32, Blocks.planks, 1, 3);
					world.setBlock(posX + 14, posY + 5, posZ + 33, Blocks.planks, 1, 3);
					world.setBlock(posX + 14, posY + 5, posZ + 34, Blocks.planks, 1, 3);
					world.setBlock(posX + 14, posY + 5, posZ + 35, Blocks.planks, 1, 3);
					world.setBlock(posX + 14, posY + 5, posZ + 36, Blocks.planks, 1, 3);
					world.setBlock(posX + 14, posY + 5, posZ + 37, Blocks.planks, 1, 3);
					world.setBlock(posX + 14, posY + 5, posZ + 38, Blocks.planks, 1, 3);
					world.setBlock(posX + 14, posY + 5, posZ + 39, Blocks.planks, 1, 3);
					world.setBlock(posX + 14, posY + 5, posZ + 40, Blocks.planks, 1, 3);
					world.setBlock(posX + 14, posY + 5, posZ + 41, Blocks.planks, 1, 3);
					world.setBlock(posX + 14, posY + 5, posZ + 42, Blocks.planks, 1, 3);
					world.setBlock(posX + 14, posY + 5, posZ + 43, Blocks.planks, 1, 3);
					world.setBlock(posX + 14, posY + 5, posZ + 44, Blocks.planks, 1, 3);
					world.setBlock(posX + 14, posY + 5, posZ + 45, Blocks.planks, 1, 3);
					world.setBlock(posX + 14, posY + 6, posZ + 10, Blocks.planks, 1, 3);
					world.setBlock(posX + 14, posY + 6, posZ + 27, Blocks.log, 1, 3);
					world.setBlock(posX + 14, posY + 6, posZ + 28, Blocks.oak_stairs, 0, 3);
					world.setBlock(posX + 14, posY + 6, posZ + 33, Blocks.stained_hardened_clay, 15, 3);
					world.setBlock(posX + 14, posY + 6, posZ + 36, Blocks.stained_hardened_clay, 15, 3);
					world.setBlock(posX + 14, posY + 6, posZ + 39, Blocks.stained_hardened_clay, 15, 3);
					world.setBlock(posX + 14, posY + 6, posZ + 42, Blocks.stained_hardened_clay, 15, 3);
					world.setBlock(posX + 14, posY + 6, posZ + 46, Blocks.planks, 1, 3);
					world.setBlock(posX + 14, posY + 6, posZ + 47, Blocks.wooden_slab, 8, 3);
					world.setBlock(posX + 14, posY + 7, posZ + 9, Blocks.planks, 1, 3);
					world.setBlock(posX + 14, posY + 7, posZ + 10, Blocks.planks, 1, 3);
					world.setBlock(posX + 14, posY + 7, posZ + 27, Blocks.planks, 1, 3);
					world.setBlock(posX + 14, posY + 7, posZ + 46, Blocks.planks, 1, 3);
					world.setBlock(posX + 14, posY + 7, posZ + 47, Blocks.planks, 1, 3);
					world.setBlock(posX + 14, posY + 8, posZ + 9, Blocks.planks, 1, 3);
					world.setBlock(posX + 14, posY + 8, posZ + 10, Blocks.planks, 1, 3);
					world.setBlock(posX + 14, posY + 8, posZ + 16, Blocks.log, 1, 3);
					world.setBlock(posX + 14, posY + 8, posZ + 27, Blocks.planks, 1, 3);
					world.setBlock(posX + 14, posY + 8, posZ + 46, Blocks.planks, 1, 3);
					world.setBlock(posX + 14, posY + 8, posZ + 47, Blocks.planks, 1, 3);
					world.setBlock(posX + 14, posY + 9, posZ + 9, Blocks.log, 8, 3);
					world.setBlock(posX + 14, posY + 9, posZ + 10, Blocks.planks, 1, 3);
					world.setBlock(posX + 14, posY + 9, posZ + 11, Blocks.planks, 1, 3);
					world.setBlock(posX + 14, posY + 9, posZ + 15, Blocks.wooden_slab, 9, 3);
					world.setBlock(posX + 14, posY + 9, posZ + 16, Blocks.iron_bars, 0, 3);
					world.setBlock(posX + 14, posY + 9, posZ + 27, Blocks.planks, 1, 3);
					world.setBlock(posX + 14, posY + 9, posZ + 29, Blocks.log, 1, 3);
					world.setBlock(posX + 14, posY + 9, posZ + 44, Blocks.log, 1, 3);
					world.setBlock(posX + 14, posY + 9, posZ + 46, Blocks.planks, 1, 3);
					world.setBlock(posX + 14, posY + 9, posZ + 47, Blocks.planks, 1, 3);
					world.setBlock(posX + 14, posY + 10, posZ + 10, Blocks.log, 1, 3);
					world.setBlock(posX + 14, posY + 10, posZ + 11, Blocks.log, 1, 3);
					world.setBlock(posX + 14, posY + 10, posZ + 12, Blocks.planks, 1, 3);
					world.setBlock(posX + 14, posY + 10, posZ + 13, Blocks.planks, 1, 3);
					world.setBlock(posX + 14, posY + 10, posZ + 14, Blocks.planks, 1, 3);
					world.setBlock(posX + 14, posY + 10, posZ + 15, Blocks.planks, 1, 3);
					world.setBlock(posX + 14, posY + 10, posZ + 16, Blocks.planks, 1, 3);
					world.setBlock(posX + 14, posY + 10, posZ + 17, Blocks.planks, 1, 3);
					world.setBlock(posX + 14, posY + 10, posZ + 18, Blocks.planks, 1, 3);
					world.setBlock(posX + 14, posY + 10, posZ + 19, Blocks.planks, 1, 3);
					world.setBlock(posX + 14, posY + 10, posZ + 20, Blocks.planks, 1, 3);
					world.setBlock(posX + 14, posY + 10, posZ + 21, Blocks.planks, 1, 3);
					world.setBlock(posX + 14, posY + 10, posZ + 22, Blocks.planks, 1, 3);
					world.setBlock(posX + 14, posY + 10, posZ + 23, Blocks.planks, 1, 3);
					world.setBlock(posX + 14, posY + 10, posZ + 24, Blocks.planks, 1, 3);
					world.setBlock(posX + 14, posY + 10, posZ + 25, Blocks.planks, 1, 3);
					world.setBlock(posX + 14, posY + 10, posZ + 26, Blocks.planks, 1, 3);
					world.setBlock(posX + 14, posY + 10, posZ + 27, Blocks.planks, 1, 3);
					world.setBlock(posX + 14, posY + 10, posZ + 28, Blocks.planks, 1, 3);
					world.setBlock(posX + 14, posY + 10, posZ + 29, Blocks.planks, 1, 3);
					world.setBlock(posX + 14, posY + 10, posZ + 30, Blocks.planks, 1, 3);
					world.setBlock(posX + 14, posY + 10, posZ + 31, Blocks.planks, 1, 3);
					world.setBlock(posX + 14, posY + 10, posZ + 32, Blocks.planks, 1, 3);
					world.setBlock(posX + 14, posY + 10, posZ + 33, Blocks.planks, 1, 3);
					world.setBlock(posX + 14, posY + 10, posZ + 34, Blocks.planks, 1, 3);
					world.setBlock(posX + 14, posY + 10, posZ + 35, Blocks.planks, 1, 3);
					world.setBlock(posX + 14, posY + 10, posZ + 36, Blocks.planks, 1, 3);
					world.setBlock(posX + 14, posY + 10, posZ + 37, Blocks.planks, 1, 3);
					world.setBlock(posX + 14, posY + 10, posZ + 38, Blocks.planks, 1, 3);
					world.setBlock(posX + 14, posY + 10, posZ + 39, Blocks.planks, 1, 3);
					world.setBlock(posX + 14, posY + 10, posZ + 40, Blocks.planks, 1, 3);
					world.setBlock(posX + 14, posY + 10, posZ + 41, Blocks.planks, 1, 3);
					world.setBlock(posX + 14, posY + 10, posZ + 42, Blocks.planks, 1, 3);
					world.setBlock(posX + 14, posY + 10, posZ + 43, Blocks.planks, 1, 3);
					world.setBlock(posX + 14, posY + 10, posZ + 44, Blocks.planks, 1, 3);
					world.setBlock(posX + 14, posY + 10, posZ + 46, Blocks.log, 1, 3);
					world.setBlock(posX + 14, posY + 10, posZ + 47, Blocks.log, 1, 3);
					world.setBlock(posX + 14, posY + 11, posZ + 10, Blocks.fence, 0, 3);
					world.setBlock(posX + 14, posY + 11, posZ + 11, Blocks.fence, 0, 3);
					world.setBlock(posX + 14, posY + 11, posZ + 17, Blocks.oak_stairs, 5, 3);
					world.setBlock(posX + 14, posY + 11, posZ + 19, Blocks.oak_stairs, 5, 3);
					world.setBlock(posX + 14, posY + 11, posZ + 23, Blocks.oak_stairs, 5, 3);
					world.setBlock(posX + 14, posY + 11, posZ + 25, Blocks.oak_stairs, 5, 3);
					world.setBlock(posX + 14, posY + 11, posZ + 29, Blocks.oak_stairs, 5, 3);
					world.setBlock(posX + 14, posY + 11, posZ + 31, Blocks.oak_stairs, 5, 3);
					world.setBlock(posX + 14, posY + 11, posZ + 35, Blocks.oak_stairs, 5, 3);
					world.setBlock(posX + 14, posY + 11, posZ + 37, Blocks.oak_stairs, 5, 3);
					world.setBlock(posX + 14, posY + 11, posZ + 39, Blocks.planks, 1, 3);
					world.setBlock(posX + 14, posY + 11, posZ + 47, Blocks.log, 1, 3);
					world.setBlock(posX + 14, posY + 12, posZ + 17, Blocks.oak_stairs, 1, 3);
					world.setBlock(posX + 14, posY + 12, posZ + 18, Blocks.stained_hardened_clay, 15, 3);
					world.setBlock(posX + 14, posY + 12, posZ + 19, Blocks.oak_stairs, 1, 3);
					world.setBlock(posX + 14, posY + 12, posZ + 23, Blocks.oak_stairs, 1, 3);
					world.setBlock(posX + 14, posY + 12, posZ + 24, Blocks.stained_hardened_clay, 15, 3);
					world.setBlock(posX + 14, posY + 12, posZ + 25, Blocks.oak_stairs, 1, 3);
					world.setBlock(posX + 14, posY + 12, posZ + 29, Blocks.oak_stairs, 1, 3);
					world.setBlock(posX + 14, posY + 12, posZ + 30, Blocks.stained_hardened_clay, 15, 3);
					world.setBlock(posX + 14, posY + 12, posZ + 31, Blocks.oak_stairs, 1, 3);
					world.setBlock(posX + 14, posY + 12, posZ + 35, Blocks.oak_stairs, 1, 3);
					world.setBlock(posX + 14, posY + 12, posZ + 36, Blocks.stained_hardened_clay, 15, 3);
					world.setBlock(posX + 14, posY + 12, posZ + 37, Blocks.oak_stairs, 1, 3);
					world.setBlock(posX + 14, posY + 12, posZ + 39, Blocks.planks, 1, 3);
					world.setBlock(posX + 14, posY + 12, posZ + 47, Blocks.log, 1, 3);
					world.setBlock(posX + 14, posY + 13, posZ + 39, Blocks.planks, 1, 3);
					world.setBlock(posX + 14, posY + 13, posZ + 47, Blocks.log, 1, 3);
					world.setBlock(posX + 14, posY + 14, posZ + 39, Blocks.planks, 1, 3);
					world.setBlock(posX + 14, posY + 14, posZ + 40, Blocks.planks, 1, 3);
					world.setBlock(posX + 14, posY + 14, posZ + 41, Blocks.planks, 1, 3);
					world.setBlock(posX + 14, posY + 14, posZ + 42, Blocks.planks, 1, 3);
					world.setBlock(posX + 14, posY + 14, posZ + 43, Blocks.planks, 1, 3);
					world.setBlock(posX + 14, posY + 14, posZ + 44, Blocks.planks, 1, 3);
					world.setBlock(posX + 14, posY + 14, posZ + 45, Blocks.planks, 1, 3);
					world.setBlock(posX + 14, posY + 14, posZ + 46, Blocks.planks, 1, 3);
					world.setBlock(posX + 14, posY + 14, posZ + 47, Blocks.log, 1, 3);
					world.setBlock(posX + 14, posY + 15, posZ + 24, Blocks.wool, 0, 3);
					world.setBlock(posX + 14, posY + 15, posZ + 25, Blocks.fence, 0, 3);
					world.setBlock(posX + 14, posY + 15, posZ + 39, Blocks.fence, 0, 3);
					world.setBlock(posX + 14, posY + 15, posZ + 46, Blocks.fence, 0, 3);
					world.setBlock(posX + 14, posY + 15, posZ + 47, Blocks.fence, 0, 3);
					world.setBlock(posX + 14, posY + 16, posZ + 23, Blocks.wool, 0, 3);
					world.setBlock(posX + 14, posY + 17, posZ + 23, Blocks.wool, 0, 3);
					world.setBlock(posX + 14, posY + 18, posZ + 24, Blocks.wool, 0, 3);
					world.setBlock(posX + 14, posY + 19, posZ + 25, Blocks.wool, 0, 3);
					world.setBlock(posX + 14, posY + 20, posZ + 25, Blocks.fence, 0, 3);
					world.setBlock(posX + 15, posY + 2, posZ + 13, Blocks.planks, 1, 3);
					world.setBlock(posX + 15, posY + 2, posZ + 14, Blocks.planks, 1, 3);
					world.setBlock(posX + 15, posY + 2, posZ + 15, Blocks.planks, 1, 3);
					world.setBlock(posX + 15, posY + 2, posZ + 16, Blocks.planks, 1, 3);
					world.setBlock(posX + 15, posY + 2, posZ + 17, Blocks.planks, 1, 3);
					world.setBlock(posX + 15, posY + 2, posZ + 18, Blocks.planks, 1, 3);
					world.setBlock(posX + 15, posY + 2, posZ + 19, Blocks.planks, 1, 3);
					world.setBlock(posX + 15, posY + 2, posZ + 20, Blocks.planks, 1, 3);
					world.setBlock(posX + 15, posY + 2, posZ + 21, Blocks.planks, 1, 3);
					world.setBlock(posX + 15, posY + 2, posZ + 22, Blocks.planks, 1, 3);
					world.setBlock(posX + 15, posY + 2, posZ + 23, Blocks.planks, 1, 3);
					world.setBlock(posX + 15, posY + 2, posZ + 24, Blocks.planks, 1, 3);
					world.setBlock(posX + 15, posY + 2, posZ + 25, Blocks.planks, 1, 3);
					world.setBlock(posX + 15, posY + 2, posZ + 26, Blocks.planks, 1, 3);
					world.setBlock(posX + 15, posY + 2, posZ + 27, Blocks.planks, 1, 3);
					world.setBlock(posX + 15, posY + 2, posZ + 28, Blocks.planks, 1, 3);
					world.setBlock(posX + 15, posY + 2, posZ + 29, Blocks.planks, 1, 3);
					world.setBlock(posX + 15, posY + 2, posZ + 30, Blocks.planks, 1, 3);
					world.setBlock(posX + 15, posY + 2, posZ + 31, Blocks.planks, 1, 3);
					world.setBlock(posX + 15, posY + 2, posZ + 32, Blocks.planks, 1, 3);
					world.setBlock(posX + 15, posY + 2, posZ + 33, Blocks.planks, 1, 3);
					world.setBlock(posX + 15, posY + 2, posZ + 34, Blocks.planks, 1, 3);
					world.setBlock(posX + 15, posY + 2, posZ + 35, Blocks.planks, 1, 3);
					world.setBlock(posX + 15, posY + 2, posZ + 36, Blocks.planks, 1, 3);
					world.setBlock(posX + 15, posY + 2, posZ + 37, Blocks.planks, 1, 3);
					world.setBlock(posX + 15, posY + 2, posZ + 38, Blocks.planks, 1, 3);
					world.setBlock(posX + 15, posY + 2, posZ + 39, Blocks.planks, 1, 3);
					world.setBlock(posX + 15, posY + 2, posZ + 40, Blocks.planks, 1, 3);
					world.setBlock(posX + 15, posY + 2, posZ + 41, Blocks.planks, 1, 3);
					world.setBlock(posX + 15, posY + 2, posZ + 42, Blocks.planks, 1, 3);
					world.setBlock(posX + 15, posY + 2, posZ + 43, Blocks.planks, 1, 3);
					world.setBlock(posX + 15, posY + 2, posZ + 44, Blocks.planks, 1, 3);
					world.setBlock(posX + 15, posY + 3, posZ + 12, Blocks.planks, 1, 3);
					world.setBlock(posX + 15, posY + 3, posZ + 19, Blocks.planks, 1, 3);
					world.setBlock(posX + 15, posY + 3, posZ + 25, Blocks.planks, 1, 3);
					world.setBlock(posX + 15, posY + 3, posZ + 26, Blocks.planks, 1, 3);
					world.setBlock(posX + 15, posY + 3, posZ + 30, Blocks.planks, 1, 3);
					world.setBlock(posX + 15, posY + 3, posZ + 32, Blocks.mob_spawner, 5, 3);
					((TileEntityMobSpawner)world.getTileEntity(posX + 15, posY + 3, posZ + 32)).func_145881_a().setEntityName("Pirate");
					world.setBlock(posX + 15, posY + 3, posZ + 39, Blocks.chest, 5, 3);
					WeightedRandomChestContent.generateChestContents(world.rand, ModMisc.pirateChest.getItems(random), (TileEntityChest)world.getTileEntity(posX + 15, posY + 3, posZ + 39), ModMisc.pirateChest.getCount(random));
					world.setBlock(posX + 15, posY + 3, posZ + 44, Blocks.planks, 1, 3);
					world.setBlock(posX + 15, posY + 4, posZ + 11, Blocks.planks, 1, 3);
					world.setBlock(posX + 15, posY + 4, posZ + 26, Blocks.planks, 1, 3);
					world.setBlock(posX + 15, posY + 4, posZ + 30, Blocks.planks, 1, 3);
					world.setBlock(posX + 15, posY + 4, posZ + 44, Blocks.planks, 1, 3);
					world.setBlock(posX + 15, posY + 4, posZ + 45, Blocks.oak_stairs, 4, 3);
					world.setBlock(posX + 15, posY + 5, posZ + 10, Blocks.planks, 1, 3);
					world.setBlock(posX + 15, posY + 5, posZ + 11, Blocks.planks, 1, 3);
					world.setBlock(posX + 15, posY + 5, posZ + 12, Blocks.planks, 1, 3);
					world.setBlock(posX + 15, posY + 5, posZ + 13, Blocks.planks, 1, 3);
					world.setBlock(posX + 15, posY + 5, posZ + 14, Blocks.planks, 1, 3);
					world.setBlock(posX + 15, posY + 5, posZ + 15, Blocks.planks, 1, 3);
					world.setBlock(posX + 15, posY + 5, posZ + 16, Blocks.planks, 1, 3);
					world.setBlock(posX + 15, posY + 5, posZ + 17, Blocks.planks, 1, 3);
					world.setBlock(posX + 15, posY + 5, posZ + 18, Blocks.planks, 1, 3);
					world.setBlock(posX + 15, posY + 5, posZ + 19, Blocks.planks, 1, 3);
					world.setBlock(posX + 15, posY + 5, posZ + 20, Blocks.planks, 1, 3);
					world.setBlock(posX + 15, posY + 5, posZ + 21, Blocks.planks, 1, 3);
					world.setBlock(posX + 15, posY + 5, posZ + 22, Blocks.planks, 1, 3);
					world.setBlock(posX + 15, posY + 5, posZ + 23, Blocks.planks, 1, 3);
					world.setBlock(posX + 15, posY + 5, posZ + 24, Blocks.planks, 1, 3);
					world.setBlock(posX + 15, posY + 5, posZ + 25, Blocks.planks, 1, 3);
					world.setBlock(posX + 15, posY + 5, posZ + 26, Blocks.planks, 1, 3);
					world.setBlock(posX + 15, posY + 5, posZ + 27, Blocks.planks, 1, 3);
					world.setBlock(posX + 15, posY + 5, posZ + 28, Blocks.planks, 1, 3);
					world.setBlock(posX + 15, posY + 5, posZ + 29, Blocks.planks, 1, 3);
					world.setBlock(posX + 15, posY + 5, posZ + 30, Blocks.planks, 1, 3);
					world.setBlock(posX + 15, posY + 5, posZ + 31, Blocks.planks, 1, 3);
					world.setBlock(posX + 15, posY + 5, posZ + 32, Blocks.planks, 1, 3);
					world.setBlock(posX + 15, posY + 5, posZ + 33, Blocks.planks, 1, 3);
					world.setBlock(posX + 15, posY + 5, posZ + 34, Blocks.planks, 1, 3);
					world.setBlock(posX + 15, posY + 5, posZ + 35, Blocks.planks, 1, 3);
					world.setBlock(posX + 15, posY + 5, posZ + 36, Blocks.planks, 1, 3);
					world.setBlock(posX + 15, posY + 5, posZ + 37, Blocks.planks, 1, 3);
					world.setBlock(posX + 15, posY + 5, posZ + 38, Blocks.planks, 1, 3);
					world.setBlock(posX + 15, posY + 5, posZ + 39, Blocks.planks, 1, 3);
					world.setBlock(posX + 15, posY + 5, posZ + 40, Blocks.planks, 1, 3);
					world.setBlock(posX + 15, posY + 5, posZ + 41, Blocks.planks, 1, 3);
					world.setBlock(posX + 15, posY + 5, posZ + 42, Blocks.planks, 1, 3);
					world.setBlock(posX + 15, posY + 5, posZ + 43, Blocks.planks, 1, 3);
					world.setBlock(posX + 15, posY + 5, posZ + 44, Blocks.planks, 1, 3);
					world.setBlock(posX + 15, posY + 5, posZ + 45, Blocks.planks, 1, 3);
					world.setBlock(posX + 15, posY + 5, posZ + 46, Blocks.oak_stairs, 4, 3);
					world.setBlock(posX + 15, posY + 6, posZ + 9, Blocks.planks, 1, 3);
					world.setBlock(posX + 15, posY + 6, posZ + 19, Blocks.log, 1, 3);
					world.setBlock(posX + 15, posY + 6, posZ + 20, Blocks.log, 1, 3);
					world.setBlock(posX + 15, posY + 6, posZ + 21, Blocks.log, 1, 3);
					world.setBlock(posX + 15, posY + 6, posZ + 22, Blocks.log, 1, 3);
					world.setBlock(posX + 15, posY + 6, posZ + 23, Blocks.log, 1, 3);
					world.setBlock(posX + 15, posY + 6, posZ + 25, Blocks.log, 1, 3);
					world.setBlock(posX + 15, posY + 6, posZ + 26, Blocks.log, 1, 3);
					world.setBlock(posX + 15, posY + 6, posZ + 27, Blocks.log, 1, 3);
					world.setBlock(posX + 15, posY + 6, posZ + 28, Blocks.log, 1, 3);
					world.setBlock(posX + 15, posY + 6, posZ + 30, Blocks.log, 1, 3);
					world.setBlock(posX + 15, posY + 6, posZ + 46, Blocks.planks, 1, 3);
					world.setBlock(posX + 15, posY + 6, posZ + 47, Blocks.wooden_slab, 8, 3);
					world.setBlock(posX + 15, posY + 7, posZ + 8, Blocks.planks, 1, 3);
					world.setBlock(posX + 15, posY + 7, posZ + 9, Blocks.planks, 1, 3);
					world.setBlock(posX + 15, posY + 7, posZ + 16, Blocks.log, 1, 3);
					world.setBlock(posX + 15, posY + 7, posZ + 19, Blocks.log, 1, 3);
					world.setBlock(posX + 15, posY + 7, posZ + 20, Blocks.planks, 1, 3);
					world.setBlock(posX + 15, posY + 7, posZ + 21, Blocks.planks, 1, 3);
					world.setBlock(posX + 15, posY + 7, posZ + 22, Blocks.planks, 1, 3);
					world.setBlock(posX + 15, posY + 7, posZ + 23, Blocks.log, 1, 3);
					world.setBlock(posX + 15, posY + 7, posZ + 25, Blocks.log, 1, 3);
					world.setBlock(posX + 15, posY + 7, posZ + 26, Blocks.planks, 1, 3);
					world.setBlock(posX + 15, posY + 7, posZ + 27, Blocks.planks, 1, 3);
					world.setBlock(posX + 15, posY + 7, posZ + 28, Blocks.log, 1, 3);
					world.setBlock(posX + 15, posY + 7, posZ + 30, Blocks.log, 1, 3);
					world.setBlock(posX + 15, posY + 7, posZ + 47, Blocks.planks, 1, 3);
					world.setBlock(posX + 15, posY + 8, posZ + 8, Blocks.planks, 1, 3);
					world.setBlock(posX + 15, posY + 8, posZ + 9, Blocks.planks, 1, 3);
					world.setBlock(posX + 15, posY + 8, posZ + 16, Blocks.log, 1, 3);
					world.setBlock(posX + 15, posY + 8, posZ + 19, Blocks.log, 1, 3);
					world.setBlock(posX + 15, posY + 8, posZ + 20, Blocks.planks, 1, 3);
					world.setBlock(posX + 15, posY + 8, posZ + 21, Blocks.planks, 1, 3);
					world.setBlock(posX + 15, posY + 8, posZ + 22, Blocks.planks, 1, 3);
					world.setBlock(posX + 15, posY + 8, posZ + 23, Blocks.log, 1, 3);
					world.setBlock(posX + 15, posY + 8, posZ + 24, Blocks.log, 1, 3);
					world.setBlock(posX + 15, posY + 8, posZ + 25, Blocks.log, 1, 3);
					world.setBlock(posX + 15, posY + 8, posZ + 26, Blocks.planks, 1, 3);
					world.setBlock(posX + 15, posY + 8, posZ + 27, Blocks.planks, 1, 3);
					world.setBlock(posX + 15, posY + 8, posZ + 28, Blocks.log, 1, 3);
					world.setBlock(posX + 15, posY + 8, posZ + 29, Blocks.log, 1, 3);
					world.setBlock(posX + 15, posY + 8, posZ + 30, Blocks.log, 1, 3);
					world.setBlock(posX + 15, posY + 8, posZ + 47, Blocks.planks, 1, 3);
					world.setBlock(posX + 15, posY + 9, posZ + 8, Blocks.log, 8, 3);
					world.setBlock(posX + 15, posY + 9, posZ + 9, Blocks.planks, 1, 3);
					world.setBlock(posX + 15, posY + 9, posZ + 10, Blocks.planks, 1, 3);
					world.setBlock(posX + 15, posY + 9, posZ + 15, Blocks.wooden_slab, 9, 3);
					world.setBlock(posX + 15, posY + 9, posZ + 16, Blocks.iron_bars, 0, 3);
					world.setBlock(posX + 15, posY + 9, posZ + 19, Blocks.log, 1, 3);
					world.setBlock(posX + 15, posY + 9, posZ + 20, Blocks.planks, 1, 3);
					world.setBlock(posX + 15, posY + 9, posZ + 21, Blocks.planks, 1, 3);
					world.setBlock(posX + 15, posY + 9, posZ + 22, Blocks.planks, 1, 3);
					world.setBlock(posX + 15, posY + 9, posZ + 23, Blocks.planks, 1, 3);
					world.setBlock(posX + 15, posY + 9, posZ + 24, Blocks.planks, 1, 3);
					world.setBlock(posX + 15, posY + 9, posZ + 25, Blocks.planks, 1, 3);
					world.setBlock(posX + 15, posY + 9, posZ + 26, Blocks.planks, 1, 3);
					world.setBlock(posX + 15, posY + 9, posZ + 27, Blocks.planks, 1, 3);
					world.setBlock(posX + 15, posY + 9, posZ + 28, Blocks.planks, 1, 3);
					world.setBlock(posX + 15, posY + 9, posZ + 29, Blocks.planks, 1, 3);
					world.setBlock(posX + 15, posY + 9, posZ + 30, Blocks.log, 1, 3);
					world.setBlock(posX + 15, posY + 9, posZ + 45, Blocks.log, 1, 3);
					world.setBlock(posX + 15, posY + 9, posZ + 47, Blocks.planks, 1, 3);
					world.setBlock(posX + 15, posY + 10, posZ + 9, Blocks.log, 1, 3);
					world.setBlock(posX + 15, posY + 10, posZ + 10, Blocks.log, 1, 3);
					world.setBlock(posX + 15, posY + 10, posZ + 11, Blocks.planks, 1, 3);
					world.setBlock(posX + 15, posY + 10, posZ + 12, Blocks.planks, 1, 3);
					world.setBlock(posX + 15, posY + 10, posZ + 13, Blocks.planks, 1, 3);
					world.setBlock(posX + 15, posY + 10, posZ + 14, Blocks.planks, 1, 3);
					world.setBlock(posX + 15, posY + 10, posZ + 15, Blocks.planks, 1, 3);
					world.setBlock(posX + 15, posY + 10, posZ + 16, Blocks.planks, 1, 3);
					world.setBlock(posX + 15, posY + 10, posZ + 17, Blocks.planks, 1, 3);
					world.setBlock(posX + 15, posY + 10, posZ + 18, Blocks.planks, 1, 3);
					world.setBlock(posX + 15, posY + 10, posZ + 19, Blocks.planks, 1, 3);
					world.setBlock(posX + 15, posY + 10, posZ + 20, Blocks.planks, 1, 3);
					world.setBlock(posX + 15, posY + 10, posZ + 21, Blocks.planks, 1, 3);
					world.setBlock(posX + 15, posY + 10, posZ + 22, Blocks.planks, 1, 3);
					world.setBlock(posX + 15, posY + 10, posZ + 23, Blocks.planks, 1, 3);
					world.setBlock(posX + 15, posY + 10, posZ + 24, Blocks.planks, 1, 3);
					world.setBlock(posX + 15, posY + 10, posZ + 25, Blocks.planks, 1, 3);
					world.setBlock(posX + 15, posY + 10, posZ + 26, Blocks.planks, 1, 3);
					world.setBlock(posX + 15, posY + 10, posZ + 27, Blocks.planks, 1, 3);
					world.setBlock(posX + 15, posY + 10, posZ + 28, Blocks.planks, 1, 3);
					world.setBlock(posX + 15, posY + 10, posZ + 29, Blocks.planks, 1, 3);
					world.setBlock(posX + 15, posY + 10, posZ + 30, Blocks.planks, 1, 3);
					world.setBlock(posX + 15, posY + 10, posZ + 31, Blocks.planks, 1, 3);
					world.setBlock(posX + 15, posY + 10, posZ + 32, Blocks.planks, 1, 3);
					world.setBlock(posX + 15, posY + 10, posZ + 33, Blocks.planks, 1, 3);
					world.setBlock(posX + 15, posY + 10, posZ + 34, Blocks.planks, 1, 3);
					world.setBlock(posX + 15, posY + 10, posZ + 35, Blocks.planks, 1, 3);
					world.setBlock(posX + 15, posY + 10, posZ + 36, Blocks.planks, 1, 3);
					world.setBlock(posX + 15, posY + 10, posZ + 37, Blocks.planks, 1, 3);
					world.setBlock(posX + 15, posY + 10, posZ + 38, Blocks.planks, 1, 3);
					world.setBlock(posX + 15, posY + 10, posZ + 39, Blocks.planks, 1, 3);
					world.setBlock(posX + 15, posY + 10, posZ + 40, Blocks.planks, 1, 3);
					world.setBlock(posX + 15, posY + 10, posZ + 41, Blocks.planks, 1, 3);
					world.setBlock(posX + 15, posY + 10, posZ + 42, Blocks.planks, 1, 3);
					world.setBlock(posX + 15, posY + 10, posZ + 43, Blocks.planks, 1, 3);
					world.setBlock(posX + 15, posY + 10, posZ + 44, Blocks.planks, 1, 3);
					world.setBlock(posX + 15, posY + 10, posZ + 45, Blocks.planks, 1, 3);
					world.setBlock(posX + 15, posY + 10, posZ + 46, Blocks.planks, 1, 3);
					world.setBlock(posX + 15, posY + 10, posZ + 47, Blocks.planks, 1, 3);
					world.setBlock(posX + 15, posY + 11, posZ + 9, Blocks.fence, 0, 3);
					world.setBlock(posX + 15, posY + 11, posZ + 10, Blocks.fence, 0, 3);
					world.setBlock(posX + 15, posY + 11, posZ + 11, Blocks.mob_spawner, 3, 3);
					((TileEntityMobSpawner)world.getTileEntity(posX + 15, posY + 11, posZ + 11)).func_145881_a().setEntityName("Pirate");
					world.setBlock(posX + 15, posY + 11, posZ + 39, Blocks.planks, 1, 3);
					world.setBlock(posX + 15, posY + 11, posZ + 46, Blocks.chest, 2, 3);
					WeightedRandomChestContent.generateChestContents(world.rand, ModMisc.pirateChest.getItems(random), (TileEntityChest)world.getTileEntity(posX + 15, posY + 11, posZ + 46), ModMisc.pirateChest.getCount(random));
					world.setBlock(posX + 15, posY + 11, posZ + 47, Blocks.planks, 1, 3);
					world.setBlock(posX + 15, posY + 12, posZ + 39, Blocks.planks, 1, 3);
					world.setBlock(posX + 15, posY + 12, posZ + 47, Blocks.planks, 1, 3);
					world.setBlock(posX + 15, posY + 13, posZ + 39, Blocks.planks, 1, 3);
					world.setBlock(posX + 15, posY + 13, posZ + 47, Blocks.planks, 1, 3);
					world.setBlock(posX + 15, posY + 14, posZ + 39, Blocks.planks, 1, 3);
					world.setBlock(posX + 15, posY + 14, posZ + 40, Blocks.planks, 1, 3);
					world.setBlock(posX + 15, posY + 14, posZ + 41, Blocks.planks, 1, 3);
					world.setBlock(posX + 15, posY + 14, posZ + 42, Blocks.planks, 1, 3);
					world.setBlock(posX + 15, posY + 14, posZ + 43, Blocks.planks, 1, 3);
					world.setBlock(posX + 15, posY + 14, posZ + 44, Blocks.planks, 1, 3);
					world.setBlock(posX + 15, posY + 14, posZ + 45, Blocks.planks, 1, 3);
					world.setBlock(posX + 15, posY + 14, posZ + 46, Blocks.planks, 1, 3);
					world.setBlock(posX + 15, posY + 14, posZ + 47, Blocks.planks, 1, 3);
					world.setBlock(posX + 15, posY + 15, posZ + 24, Blocks.wool, 0, 3);
					world.setBlock(posX + 15, posY + 15, posZ + 25, Blocks.fence, 0, 3);
					world.setBlock(posX + 15, posY + 15, posZ + 39, Blocks.fence, 0, 3);
					world.setBlock(posX + 15, posY + 15, posZ + 43, Blocks.oak_stairs, 0, 3);
					world.setBlock(posX + 15, posY + 15, posZ + 47, Blocks.fence, 0, 3);
					world.setBlock(posX + 15, posY + 16, posZ + 23, Blocks.wool, 0, 3);
					world.setBlock(posX + 15, posY + 17, posZ + 23, Blocks.wool, 0, 3);
					world.setBlock(posX + 15, posY + 18, posZ + 24, Blocks.wool, 0, 3);
					world.setBlock(posX + 15, posY + 19, posZ + 25, Blocks.wool, 0, 3);
					world.setBlock(posX + 15, posY + 20, posZ + 25, Blocks.fence, 0, 3);
					world.setBlock(posX + 15, posY + 21, posZ + 24, Blocks.fence, 0, 3);
					world.setBlock(posX + 15, posY + 21, posZ + 25, Blocks.fence, 0, 3);
					world.setBlock(posX + 15, posY + 21, posZ + 26, Blocks.fence, 0, 3);
					world.setBlock(posX + 15, posY + 21, posZ + 27, Blocks.fence, 0, 3);
					world.setBlock(posX + 15, posY + 22, posZ + 24, Blocks.log, 0, 3);
					world.setBlock(posX + 15, posY + 22, posZ + 25, Blocks.log, 0, 3);
					world.setBlock(posX + 15, posY + 22, posZ + 26, Blocks.log, 0, 3);
					world.setBlock(posX + 15, posY + 22, posZ + 27, Blocks.log, 0, 3);
					world.setBlock(posX + 16, posY + 1, posZ + 13, Blocks.planks, 1, 3);
					world.setBlock(posX + 16, posY + 1, posZ + 14, Blocks.planks, 1, 3);
					world.setBlock(posX + 16, posY + 1, posZ + 15, Blocks.planks, 1, 3);
					world.setBlock(posX + 16, posY + 1, posZ + 16, Blocks.planks, 1, 3);
					world.setBlock(posX + 16, posY + 1, posZ + 17, Blocks.planks, 1, 3);
					world.setBlock(posX + 16, posY + 1, posZ + 18, Blocks.planks, 1, 3);
					world.setBlock(posX + 16, posY + 1, posZ + 19, Blocks.planks, 1, 3);
					world.setBlock(posX + 16, posY + 1, posZ + 20, Blocks.planks, 1, 3);
					world.setBlock(posX + 16, posY + 1, posZ + 21, Blocks.planks, 1, 3);
					world.setBlock(posX + 16, posY + 1, posZ + 22, Blocks.planks, 1, 3);
					world.setBlock(posX + 16, posY + 1, posZ + 23, Blocks.planks, 1, 3);
					world.setBlock(posX + 16, posY + 1, posZ + 24, Blocks.planks, 1, 3);
					world.setBlock(posX + 16, posY + 1, posZ + 25, Blocks.planks, 1, 3);
					world.setBlock(posX + 16, posY + 1, posZ + 26, Blocks.planks, 1, 3);
					world.setBlock(posX + 16, posY + 1, posZ + 27, Blocks.planks, 1, 3);
					world.setBlock(posX + 16, posY + 1, posZ + 28, Blocks.planks, 1, 3);
					world.setBlock(posX + 16, posY + 1, posZ + 29, Blocks.planks, 1, 3);
					world.setBlock(posX + 16, posY + 1, posZ + 30, Blocks.planks, 1, 3);
					world.setBlock(posX + 16, posY + 1, posZ + 31, Blocks.planks, 1, 3);
					world.setBlock(posX + 16, posY + 1, posZ + 32, Blocks.planks, 1, 3);
					world.setBlock(posX + 16, posY + 1, posZ + 33, Blocks.planks, 1, 3);
					world.setBlock(posX + 16, posY + 1, posZ + 34, Blocks.planks, 1, 3);
					world.setBlock(posX + 16, posY + 1, posZ + 35, Blocks.planks, 1, 3);
					world.setBlock(posX + 16, posY + 1, posZ + 36, Blocks.planks, 1, 3);
					world.setBlock(posX + 16, posY + 1, posZ + 37, Blocks.planks, 1, 3);
					world.setBlock(posX + 16, posY + 1, posZ + 38, Blocks.planks, 1, 3);
					world.setBlock(posX + 16, posY + 1, posZ + 39, Blocks.planks, 1, 3);
					world.setBlock(posX + 16, posY + 1, posZ + 40, Blocks.planks, 1, 3);
					world.setBlock(posX + 16, posY + 1, posZ + 41, Blocks.planks, 1, 3);
					world.setBlock(posX + 16, posY + 1, posZ + 42, Blocks.planks, 1, 3);
					world.setBlock(posX + 16, posY + 1, posZ + 43, Blocks.planks, 1, 3);
					world.setBlock(posX + 16, posY + 1, posZ + 44, Blocks.planks, 1, 3);
					world.setBlock(posX + 16, posY + 2, posZ + 12, Blocks.planks, 1, 3);
					world.setBlock(posX + 16, posY + 2, posZ + 26, Blocks.planks, 1, 3);
					world.setBlock(posX + 16, posY + 2, posZ + 30, Blocks.planks, 1, 3);
					world.setBlock(posX + 16, posY + 2, posZ + 44, Blocks.planks, 1, 3);
					world.setBlock(posX + 16, posY + 3, posZ + 11, Blocks.planks, 1, 3);
					world.setBlock(posX + 16, posY + 3, posZ + 19, Blocks.planks, 1, 3);
					world.setBlock(posX + 16, posY + 3, posZ + 25, Blocks.planks, 1, 3);
					world.setBlock(posX + 16, posY + 3, posZ + 26, Blocks.planks, 1, 3);
					world.setBlock(posX + 16, posY + 3, posZ + 30, Blocks.planks, 1, 3);
					world.setBlock(posX + 16, posY + 3, posZ + 44, Blocks.planks, 1, 3);
					world.setBlock(posX + 16, posY + 4, posZ + 10, Blocks.planks, 1, 3);
					world.setBlock(posX + 16, posY + 4, posZ + 16, Blocks.planks, 1, 3);
					world.setBlock(posX + 16, posY + 4, posZ + 26, Blocks.planks, 1, 3);
					world.setBlock(posX + 16, posY + 4, posZ + 30, Blocks.planks, 1, 3);
					world.setBlock(posX + 16, posY + 4, posZ + 44, Blocks.planks, 1, 3);
					world.setBlock(posX + 16, posY + 4, posZ + 45, Blocks.oak_stairs, 7, 3);
					world.setBlock(posX + 16, posY + 5, posZ + 9, Blocks.planks, 1, 3);
					world.setBlock(posX + 16, posY + 5, posZ + 10, Blocks.planks, 1, 3);
					world.setBlock(posX + 16, posY + 5, posZ + 11, Blocks.planks, 1, 3);
					world.setBlock(posX + 16, posY + 5, posZ + 12, Blocks.planks, 1, 3);
					world.setBlock(posX + 16, posY + 5, posZ + 13, Blocks.planks, 1, 3);
					world.setBlock(posX + 16, posY + 5, posZ + 14, Blocks.planks, 1, 3);
					world.setBlock(posX + 16, posY + 5, posZ + 15, Blocks.planks, 1, 3);
					world.setBlock(posX + 16, posY + 5, posZ + 17, Blocks.planks, 1, 3);
					world.setBlock(posX + 16, posY + 5, posZ + 18, Blocks.planks, 1, 3);
					world.setBlock(posX + 16, posY + 5, posZ + 19, Blocks.planks, 1, 3);
					world.setBlock(posX + 16, posY + 5, posZ + 20, Blocks.planks, 1, 3);
					world.setBlock(posX + 16, posY + 5, posZ + 21, Blocks.planks, 1, 3);
					world.setBlock(posX + 16, posY + 5, posZ + 22, Blocks.planks, 1, 3);
					world.setBlock(posX + 16, posY + 5, posZ + 23, Blocks.planks, 1, 3);
					world.setBlock(posX + 16, posY + 5, posZ + 24, Blocks.planks, 1, 3);
					world.setBlock(posX + 16, posY + 5, posZ + 25, Blocks.planks, 1, 3);
					world.setBlock(posX + 16, posY + 5, posZ + 26, Blocks.planks, 1, 3);
					world.setBlock(posX + 16, posY + 5, posZ + 27, Blocks.planks, 1, 3);
					world.setBlock(posX + 16, posY + 5, posZ + 28, Blocks.planks, 1, 3);
					world.setBlock(posX + 16, posY + 5, posZ + 29, Blocks.planks, 1, 3);
					world.setBlock(posX + 16, posY + 5, posZ + 30, Blocks.planks, 1, 3);
					world.setBlock(posX + 16, posY + 5, posZ + 31, Blocks.planks, 1, 3);
					world.setBlock(posX + 16, posY + 5, posZ + 32, Blocks.planks, 1, 3);
					world.setBlock(posX + 16, posY + 5, posZ + 33, Blocks.planks, 1, 3);
					world.setBlock(posX + 16, posY + 5, posZ + 34, Blocks.planks, 1, 3);
					world.setBlock(posX + 16, posY + 5, posZ + 35, Blocks.planks, 1, 3);
					world.setBlock(posX + 16, posY + 5, posZ + 36, Blocks.planks, 1, 3);
					world.setBlock(posX + 16, posY + 5, posZ + 37, Blocks.planks, 1, 3);
					world.setBlock(posX + 16, posY + 5, posZ + 38, Blocks.planks, 1, 3);
					world.setBlock(posX + 16, posY + 5, posZ + 39, Blocks.planks, 1, 3);
					world.setBlock(posX + 16, posY + 5, posZ + 40, Blocks.planks, 1, 3);
					world.setBlock(posX + 16, posY + 5, posZ + 41, Blocks.planks, 1, 3);
					world.setBlock(posX + 16, posY + 5, posZ + 42, Blocks.planks, 1, 3);
					world.setBlock(posX + 16, posY + 5, posZ + 43, Blocks.planks, 1, 3);
					world.setBlock(posX + 16, posY + 5, posZ + 44, Blocks.planks, 1, 3);
					world.setBlock(posX + 16, posY + 5, posZ + 45, Blocks.planks, 1, 3);
					world.setBlock(posX + 16, posY + 5, posZ + 46, Blocks.oak_stairs, 7, 3);
					world.setBlock(posX + 16, posY + 6, posZ + 8, Blocks.planks, 1, 3);
					world.setBlock(posX + 16, posY + 6, posZ + 16, Blocks.wooden_slab, 9, 3);
					world.setBlock(posX + 16, posY + 6, posZ + 19, Blocks.log, 1, 3);
					world.setBlock(posX + 16, posY + 6, posZ + 30, Blocks.log, 1, 3);
					world.setBlock(posX + 16, posY + 6, posZ + 46, Blocks.planks, 1, 3);
					world.setBlock(posX + 16, posY + 6, posZ + 47, Blocks.wooden_slab, 8, 3);
					world.setBlock(posX + 16, posY + 7, posZ + 7, Blocks.planks, 1, 3);
					world.setBlock(posX + 16, posY + 7, posZ + 8, Blocks.planks, 1, 3);
					world.setBlock(posX + 16, posY + 7, posZ + 16, Blocks.iron_bars, 0, 3);
					world.setBlock(posX + 16, posY + 7, posZ + 19, Blocks.planks, 1, 3);
					world.setBlock(posX + 16, posY + 7, posZ + 30, Blocks.planks, 1, 3);
					world.setBlock(posX + 16, posY + 7, posZ + 47, Blocks.planks, 1, 3);
					world.setBlock(posX + 16, posY + 8, posZ + 7, Blocks.planks, 1, 3);
					world.setBlock(posX + 16, posY + 8, posZ + 8, Blocks.planks, 1, 3);
					world.setBlock(posX + 16, posY + 8, posZ + 16, Blocks.iron_bars, 0, 3);
					world.setBlock(posX + 16, posY + 8, posZ + 19, Blocks.planks, 1, 3);
					world.setBlock(posX + 16, posY + 8, posZ + 30, Blocks.planks, 1, 3);
					world.setBlock(posX + 16, posY + 8, posZ + 47, Blocks.planks, 1, 3);
					world.setBlock(posX + 16, posY + 9, posZ + 7, Blocks.log, 8, 3);
					world.setBlock(posX + 16, posY + 9, posZ + 8, Blocks.planks, 1, 3);
					world.setBlock(posX + 16, posY + 9, posZ + 9, Blocks.planks, 1, 3);
					world.setBlock(posX + 16, posY + 9, posZ + 15, Blocks.wooden_slab, 9, 3);
					world.setBlock(posX + 16, posY + 9, posZ + 16, Blocks.iron_bars, 0, 3);
					world.setBlock(posX + 16, posY + 9, posZ + 19, Blocks.planks, 1, 3);
					world.setBlock(posX + 16, posY + 9, posZ + 30, Blocks.planks, 1, 3);
					world.setBlock(posX + 16, posY + 9, posZ + 46, Blocks.log, 1, 3);
					world.setBlock(posX + 16, posY + 9, posZ + 47, Blocks.planks, 1, 3);
					world.setBlock(posX + 16, posY + 10, posZ + 8, Blocks.log, 1, 3);
					world.setBlock(posX + 16, posY + 10, posZ + 9, Blocks.log, 1, 3);
					world.setBlock(posX + 16, posY + 10, posZ + 10, Blocks.planks, 1, 3);
					world.setBlock(posX + 16, posY + 10, posZ + 11, Blocks.planks, 1, 3);
					world.setBlock(posX + 16, posY + 10, posZ + 12, Blocks.planks, 1, 3);
					world.setBlock(posX + 16, posY + 10, posZ + 13, Blocks.planks, 1, 3);
					world.setBlock(posX + 16, posY + 10, posZ + 14, Blocks.planks, 1, 3);
					world.setBlock(posX + 16, posY + 10, posZ + 15, Blocks.planks, 1, 3);
					world.setBlock(posX + 16, posY + 10, posZ + 16, Blocks.planks, 1, 3);
					world.setBlock(posX + 16, posY + 10, posZ + 17, Blocks.planks, 1, 3);
					world.setBlock(posX + 16, posY + 10, posZ + 18, Blocks.planks, 1, 3);
					world.setBlock(posX + 16, posY + 10, posZ + 19, Blocks.planks, 1, 3);
					world.setBlock(posX + 16, posY + 10, posZ + 20, Blocks.planks, 1, 3);
					world.setBlock(posX + 16, posY + 10, posZ + 21, Blocks.planks, 1, 3);
					world.setBlock(posX + 16, posY + 10, posZ + 22, Blocks.planks, 1, 3);
					world.setBlock(posX + 16, posY + 10, posZ + 23, Blocks.planks, 1, 3);
					world.setBlock(posX + 16, posY + 10, posZ + 24, Blocks.planks, 1, 3);
					world.setBlock(posX + 16, posY + 10, posZ + 25, Blocks.planks, 1, 3);
					world.setBlock(posX + 16, posY + 10, posZ + 26, Blocks.planks, 1, 3);
					world.setBlock(posX + 16, posY + 10, posZ + 27, Blocks.planks, 1, 3);
					world.setBlock(posX + 16, posY + 10, posZ + 28, Blocks.planks, 1, 3);
					world.setBlock(posX + 16, posY + 10, posZ + 29, Blocks.planks, 1, 3);
					world.setBlock(posX + 16, posY + 10, posZ + 30, Blocks.planks, 1, 3);
					world.setBlock(posX + 16, posY + 10, posZ + 31, Blocks.planks, 1, 3);
					world.setBlock(posX + 16, posY + 10, posZ + 32, Blocks.planks, 1, 3);
					world.setBlock(posX + 16, posY + 10, posZ + 33, Blocks.planks, 1, 3);
					world.setBlock(posX + 16, posY + 10, posZ + 34, Blocks.planks, 1, 3);
					world.setBlock(posX + 16, posY + 10, posZ + 35, Blocks.planks, 1, 3);
					world.setBlock(posX + 16, posY + 10, posZ + 36, Blocks.planks, 1, 3);
					world.setBlock(posX + 16, posY + 10, posZ + 37, Blocks.planks, 1, 3);
					world.setBlock(posX + 16, posY + 10, posZ + 38, Blocks.planks, 1, 3);
					world.setBlock(posX + 16, posY + 10, posZ + 39, Blocks.planks, 1, 3);
					world.setBlock(posX + 16, posY + 10, posZ + 40, Blocks.planks, 1, 3);
					world.setBlock(posX + 16, posY + 10, posZ + 41, Blocks.planks, 1, 3);
					world.setBlock(posX + 16, posY + 10, posZ + 42, Blocks.planks, 1, 3);
					world.setBlock(posX + 16, posY + 10, posZ + 43, Blocks.planks, 1, 3);
					world.setBlock(posX + 16, posY + 10, posZ + 44, Blocks.planks, 1, 3);
					world.setBlock(posX + 16, posY + 10, posZ + 45, Blocks.planks, 1, 3);
					world.setBlock(posX + 16, posY + 10, posZ + 46, Blocks.planks, 1, 3);
					world.setBlock(posX + 16, posY + 10, posZ + 47, Blocks.planks, 1, 3);
					world.setBlock(posX + 16, posY + 11, posZ + 8, Blocks.fence, 0, 3);
					world.setBlock(posX + 16, posY + 11, posZ + 9, Blocks.fence, 0, 3);
					world.setBlock(posX + 16, posY + 11, posZ + 11, Blocks.oak_stairs, 6, 3);
					world.setBlock(posX + 16, posY + 11, posZ + 12, Blocks.oak_stairs, 7, 3);
					world.setBlock(posX + 16, posY + 11, posZ + 39, Blocks.log, 1, 3);
					world.setBlock(posX + 16, posY + 11, posZ + 46, Blocks.mob_spawner, 2, 3);
					((TileEntityMobSpawner)world.getTileEntity(posX + 16, posY + 11, posZ + 46)).func_145881_a().setEntityName("Pirate");
					world.setBlock(posX + 16, posY + 11, posZ + 47, Blocks.planks, 1, 3);
					world.setBlock(posX + 16, posY + 12, posZ + 11, Blocks.oak_stairs, 2, 3);
					world.setBlock(posX + 16, posY + 12, posZ + 12, Blocks.oak_stairs, 3, 3);
					world.setBlock(posX + 16, posY + 12, posZ + 39, Blocks.log, 1, 3);
					world.setBlock(posX + 16, posY + 12, posZ + 47, Blocks.planks, 1, 3);
					world.setBlock(posX + 16, posY + 13, posZ + 39, Blocks.log, 1, 3);
					world.setBlock(posX + 16, posY + 13, posZ + 47, Blocks.planks, 1, 3);
					world.setBlock(posX + 16, posY + 14, posZ + 38, Blocks.wooden_slab, 1, 3);
					world.setBlock(posX + 16, posY + 14, posZ + 39, Blocks.planks, 1, 3);
					world.setBlock(posX + 16, posY + 14, posZ + 40, Blocks.planks, 1, 3);
					world.setBlock(posX + 16, posY + 14, posZ + 41, Blocks.planks, 1, 3);
					world.setBlock(posX + 16, posY + 14, posZ + 42, Blocks.planks, 1, 3);
					world.setBlock(posX + 16, posY + 14, posZ + 43, Blocks.planks, 1, 3);
					world.setBlock(posX + 16, posY + 14, posZ + 44, Blocks.planks, 1, 3);
					world.setBlock(posX + 16, posY + 14, posZ + 45, Blocks.planks, 1, 3);
					world.setBlock(posX + 16, posY + 14, posZ + 46, Blocks.planks, 1, 3);
					world.setBlock(posX + 16, posY + 14, posZ + 47, Blocks.planks, 1, 3);
					world.setBlock(posX + 16, posY + 15, posZ + 24, Blocks.wool, 0, 3);
					world.setBlock(posX + 16, posY + 15, posZ + 25, Blocks.fence, 0, 3);
					world.setBlock(posX + 16, posY + 15, posZ + 39, Blocks.fence, 0, 3);
					world.setBlock(posX + 16, posY + 15, posZ + 43, Blocks.oak_stairs, 2, 3);
					world.setBlock(posX + 16, posY + 15, posZ + 47, Blocks.fence, 0, 3);
					world.setBlock(posX + 16, posY + 16, posZ + 23, Blocks.wool, 0, 3);
					world.setBlock(posX + 16, posY + 17, posZ + 23, Blocks.wool, 0, 3);
					world.setBlock(posX + 16, posY + 18, posZ + 24, Blocks.wool, 0, 3);
					world.setBlock(posX + 16, posY + 19, posZ + 25, Blocks.wool, 0, 3);
					world.setBlock(posX + 16, posY + 20, posZ + 25, Blocks.fence, 0, 3);
					world.setBlock(posX + 16, posY + 21, posZ + 24, Blocks.fence, 0, 3);
					world.setBlock(posX + 16, posY + 21, posZ + 25, Blocks.log, 4, 3);
					world.setBlock(posX + 16, posY + 21, posZ + 26, Blocks.log, 4, 3);
					world.setBlock(posX + 16, posY + 21, posZ + 27, Blocks.fence, 0, 3);
					world.setBlock(posX + 16, posY + 22, posZ + 24, Blocks.log, 0, 3);
					world.setBlock(posX + 16, posY + 22, posZ + 27, Blocks.log, 0, 3);
					world.setBlock(posX + 17, posY + 0, posZ + 13, Blocks.planks, 1, 3);
					world.setBlock(posX + 17, posY + 0, posZ + 14, Blocks.planks, 1, 3);
					world.setBlock(posX + 17, posY + 0, posZ + 15, Blocks.planks, 1, 3);
					world.setBlock(posX + 17, posY + 0, posZ + 16, Blocks.planks, 1, 3);
					world.setBlock(posX + 17, posY + 0, posZ + 17, Blocks.planks, 1, 3);
					world.setBlock(posX + 17, posY + 0, posZ + 18, Blocks.planks, 1, 3);
					world.setBlock(posX + 17, posY + 0, posZ + 19, Blocks.planks, 1, 3);
					world.setBlock(posX + 17, posY + 0, posZ + 20, Blocks.planks, 1, 3);
					world.setBlock(posX + 17, posY + 0, posZ + 21, Blocks.planks, 1, 3);
					world.setBlock(posX + 17, posY + 0, posZ + 22, Blocks.planks, 1, 3);
					world.setBlock(posX + 17, posY + 0, posZ + 23, Blocks.planks, 1, 3);
					world.setBlock(posX + 17, posY + 0, posZ + 24, Blocks.planks, 1, 3);
					world.setBlock(posX + 17, posY + 0, posZ + 25, Blocks.planks, 1, 3);
					world.setBlock(posX + 17, posY + 0, posZ + 26, Blocks.planks, 1, 3);
					world.setBlock(posX + 17, posY + 0, posZ + 27, Blocks.planks, 1, 3);
					world.setBlock(posX + 17, posY + 0, posZ + 28, Blocks.planks, 1, 3);
					world.setBlock(posX + 17, posY + 0, posZ + 29, Blocks.planks, 1, 3);
					world.setBlock(posX + 17, posY + 0, posZ + 30, Blocks.planks, 1, 3);
					world.setBlock(posX + 17, posY + 0, posZ + 31, Blocks.planks, 1, 3);
					world.setBlock(posX + 17, posY + 0, posZ + 32, Blocks.planks, 1, 3);
					world.setBlock(posX + 17, posY + 0, posZ + 33, Blocks.planks, 1, 3);
					world.setBlock(posX + 17, posY + 0, posZ + 34, Blocks.planks, 1, 3);
					world.setBlock(posX + 17, posY + 0, posZ + 35, Blocks.planks, 1, 3);
					world.setBlock(posX + 17, posY + 0, posZ + 36, Blocks.planks, 1, 3);
					world.setBlock(posX + 17, posY + 0, posZ + 37, Blocks.planks, 1, 3);
					world.setBlock(posX + 17, posY + 0, posZ + 38, Blocks.planks, 1, 3);
					world.setBlock(posX + 17, posY + 0, posZ + 39, Blocks.planks, 1, 3);
					world.setBlock(posX + 17, posY + 0, posZ + 40, Blocks.planks, 1, 3);
					world.setBlock(posX + 17, posY + 0, posZ + 41, Blocks.planks, 1, 3);
					world.setBlock(posX + 17, posY + 0, posZ + 42, Blocks.planks, 1, 3);
					world.setBlock(posX + 17, posY + 0, posZ + 43, Blocks.planks, 1, 3);
					world.setBlock(posX + 17, posY + 0, posZ + 44, Blocks.planks, 1, 3);
					world.setBlock(posX + 17, posY + 1, posZ + 12, Blocks.planks, 1, 3);
					world.setBlock(posX + 17, posY + 1, posZ + 30, Blocks.planks, 1, 3);
					world.setBlock(posX + 17, posY + 1, posZ + 31, Blocks.planks, 1, 3);
					world.setBlock(posX + 17, posY + 1, posZ + 32, Blocks.planks, 1, 3);
					world.setBlock(posX + 17, posY + 1, posZ + 33, Blocks.planks, 1, 3);
					world.setBlock(posX + 17, posY + 1, posZ + 34, Blocks.planks, 1, 3);
					world.setBlock(posX + 17, posY + 1, posZ + 35, Blocks.planks, 1, 3);
					world.setBlock(posX + 17, posY + 1, posZ + 36, Blocks.planks, 1, 3);
					world.setBlock(posX + 17, posY + 1, posZ + 37, Blocks.planks, 1, 3);
					world.setBlock(posX + 17, posY + 1, posZ + 38, Blocks.planks, 1, 3);
					world.setBlock(posX + 17, posY + 1, posZ + 39, Blocks.planks, 1, 3);
					world.setBlock(posX + 17, posY + 1, posZ + 40, Blocks.planks, 1, 3);
					world.setBlock(posX + 17, posY + 1, posZ + 41, Blocks.planks, 1, 3);
					world.setBlock(posX + 17, posY + 1, posZ + 42, Blocks.planks, 1, 3);
					world.setBlock(posX + 17, posY + 1, posZ + 43, Blocks.planks, 1, 3);
					world.setBlock(posX + 17, posY + 1, posZ + 44, Blocks.planks, 1, 3);
					world.setBlock(posX + 17, posY + 2, posZ + 11, Blocks.planks, 1, 3);
					world.setBlock(posX + 17, posY + 2, posZ + 26, Blocks.planks, 1, 3);
					world.setBlock(posX + 17, posY + 2, posZ + 30, Blocks.planks, 1, 3);
					world.setBlock(posX + 17, posY + 2, posZ + 44, Blocks.planks, 1, 3);
					world.setBlock(posX + 17, posY + 3, posZ + 10, Blocks.planks, 1, 3);
					world.setBlock(posX + 17, posY + 3, posZ + 16, Blocks.planks, 1, 3);
					world.setBlock(posX + 17, posY + 3, posZ + 17, Blocks.planks, 1, 3);
					world.setBlock(posX + 17, posY + 3, posZ + 18, Blocks.planks, 1, 3);
					world.setBlock(posX + 17, posY + 3, posZ + 19, Blocks.planks, 1, 3);
					world.setBlock(posX + 17, posY + 3, posZ + 25, Blocks.planks, 1, 3);
					world.setBlock(posX + 17, posY + 3, posZ + 26, Blocks.planks, 1, 3);
					world.setBlock(posX + 17, posY + 3, posZ + 30, Blocks.planks, 1, 3);
					world.setBlock(posX + 17, posY + 3, posZ + 44, Blocks.planks, 1, 3);
					world.setBlock(posX + 17, posY + 4, posZ + 9, Blocks.planks, 1, 3);
					world.setBlock(posX + 17, posY + 4, posZ + 26, Blocks.planks, 1, 3);
					world.setBlock(posX + 17, posY + 4, posZ + 30, Blocks.planks, 1, 3);
					world.setBlock(posX + 17, posY + 4, posZ + 44, Blocks.planks, 1, 3);
					world.setBlock(posX + 17, posY + 4, posZ + 45, Blocks.oak_stairs, 7, 3);
					world.setBlock(posX + 17, posY + 5, posZ + 8, Blocks.planks, 1, 3);
					world.setBlock(posX + 17, posY + 5, posZ + 9, Blocks.planks, 1, 3);
					world.setBlock(posX + 17, posY + 5, posZ + 10, Blocks.planks, 1, 3);
					world.setBlock(posX + 17, posY + 5, posZ + 11, Blocks.planks, 1, 3);
					world.setBlock(posX + 17, posY + 5, posZ + 12, Blocks.planks, 1, 3);
					world.setBlock(posX + 17, posY + 5, posZ + 13, Blocks.planks, 1, 3);
					world.setBlock(posX + 17, posY + 5, posZ + 14, Blocks.planks, 1, 3);
					world.setBlock(posX + 17, posY + 5, posZ + 15, Blocks.planks, 1, 3);
					world.setBlock(posX + 17, posY + 5, posZ + 17, Blocks.planks, 1, 3);
					world.setBlock(posX + 17, posY + 5, posZ + 18, Blocks.planks, 1, 3);
					world.setBlock(posX + 17, posY + 5, posZ + 19, Blocks.planks, 1, 3);
					world.setBlock(posX + 17, posY + 5, posZ + 20, Blocks.planks, 1, 3);
					world.setBlock(posX + 17, posY + 5, posZ + 21, Blocks.planks, 1, 3);
					world.setBlock(posX + 17, posY + 5, posZ + 22, Blocks.planks, 1, 3);
					world.setBlock(posX + 17, posY + 5, posZ + 23, Blocks.planks, 1, 3);
					world.setBlock(posX + 17, posY + 5, posZ + 24, Blocks.planks, 1, 3);
					world.setBlock(posX + 17, posY + 5, posZ + 25, Blocks.planks, 1, 3);
					world.setBlock(posX + 17, posY + 5, posZ + 26, Blocks.planks, 1, 3);
					world.setBlock(posX + 17, posY + 5, posZ + 27, Blocks.planks, 1, 3);
					world.setBlock(posX + 17, posY + 5, posZ + 28, Blocks.planks, 1, 3);
					world.setBlock(posX + 17, posY + 5, posZ + 29, Blocks.planks, 1, 3);
					world.setBlock(posX + 17, posY + 5, posZ + 30, Blocks.planks, 1, 3);
					world.setBlock(posX + 17, posY + 5, posZ + 32, Blocks.planks, 1, 3);
					world.setBlock(posX + 17, posY + 5, posZ + 33, Blocks.planks, 1, 3);
					world.setBlock(posX + 17, posY + 5, posZ + 34, Blocks.planks, 1, 3);
					world.setBlock(posX + 17, posY + 5, posZ + 35, Blocks.planks, 1, 3);
					world.setBlock(posX + 17, posY + 5, posZ + 36, Blocks.planks, 1, 3);
					world.setBlock(posX + 17, posY + 5, posZ + 37, Blocks.planks, 1, 3);
					world.setBlock(posX + 17, posY + 5, posZ + 38, Blocks.planks, 1, 3);
					world.setBlock(posX + 17, posY + 5, posZ + 39, Blocks.planks, 1, 3);
					world.setBlock(posX + 17, posY + 5, posZ + 40, Blocks.planks, 1, 3);
					world.setBlock(posX + 17, posY + 5, posZ + 41, Blocks.planks, 1, 3);
					world.setBlock(posX + 17, posY + 5, posZ + 42, Blocks.planks, 1, 3);
					world.setBlock(posX + 17, posY + 5, posZ + 43, Blocks.planks, 1, 3);
					world.setBlock(posX + 17, posY + 5, posZ + 44, Blocks.planks, 1, 3);
					world.setBlock(posX + 17, posY + 5, posZ + 45, Blocks.planks, 1, 3);
					world.setBlock(posX + 17, posY + 5, posZ + 46, Blocks.oak_stairs, 7, 3);
					world.setBlock(posX + 17, posY + 6, posZ + 7, Blocks.planks, 1, 3);
					world.setBlock(posX + 17, posY + 6, posZ + 16, Blocks.log, 1, 3);
					world.setBlock(posX + 17, posY + 6, posZ + 19, Blocks.log, 1, 3);
					world.setBlock(posX + 17, posY + 6, posZ + 30, Blocks.log, 1, 3);
					world.setBlock(posX + 17, posY + 6, posZ + 46, Blocks.planks, 1, 3);
					world.setBlock(posX + 17, posY + 6, posZ + 47, Blocks.wooden_slab, 8, 3);
					world.setBlock(posX + 17, posY + 7, posZ + 6, Blocks.planks, 1, 3);
					world.setBlock(posX + 17, posY + 7, posZ + 7, Blocks.planks, 1, 3);
					world.setBlock(posX + 17, posY + 7, posZ + 16, Blocks.iron_bars, 0, 3);
					world.setBlock(posX + 17, posY + 7, posZ + 19, Blocks.log, 1, 3);
					world.setBlock(posX + 17, posY + 7, posZ + 30, Blocks.planks, 1, 3);
					world.setBlock(posX + 17, posY + 7, posZ + 47, Blocks.planks, 1, 3);
					world.setBlock(posX + 17, posY + 8, posZ + 5, Blocks.planks, 1, 3);
					world.setBlock(posX + 17, posY + 8, posZ + 6, Blocks.planks, 1, 3);
					world.setBlock(posX + 17, posY + 8, posZ + 7, Blocks.planks, 1, 3);
					world.setBlock(posX + 17, posY + 8, posZ + 16, Blocks.iron_bars, 0, 3);
					world.setBlock(posX + 17, posY + 8, posZ + 19, Blocks.planks, 1, 3);
					world.setBlock(posX + 17, posY + 8, posZ + 30, Blocks.planks, 1, 3);
					world.setBlock(posX + 17, posY + 8, posZ + 47, Blocks.planks, 1, 3);
					world.setBlock(posX + 17, posY + 9, posZ + 4, Blocks.planks, 1, 3);
					world.setBlock(posX + 17, posY + 9, posZ + 5, Blocks.planks, 1, 3);
					world.setBlock(posX + 17, posY + 9, posZ + 6, Blocks.planks, 1, 3);
					world.setBlock(posX + 17, posY + 9, posZ + 7, Blocks.planks, 1, 3);
					world.setBlock(posX + 17, posY + 9, posZ + 8, Blocks.planks, 1, 3);
					world.setBlock(posX + 17, posY + 9, posZ + 15, Blocks.wooden_slab, 9, 3);
					world.setBlock(posX + 17, posY + 9, posZ + 16, Blocks.iron_bars, 0, 3);
					world.setBlock(posX + 17, posY + 9, posZ + 19, Blocks.planks, 1, 3);
					world.setBlock(posX + 17, posY + 9, posZ + 30, Blocks.planks, 1, 3);
					world.setBlock(posX + 17, posY + 9, posZ + 45, Blocks.log, 1, 3);
					world.setBlock(posX + 17, posY + 9, posZ + 47, Blocks.planks, 1, 3);
					world.setBlock(posX + 17, posY + 10, posZ + 3, Blocks.log, 1, 3);
					world.setBlock(posX + 17, posY + 10, posZ + 4, Blocks.log, 1, 3);
					world.setBlock(posX + 17, posY + 10, posZ + 5, Blocks.log, 1, 3);
					world.setBlock(posX + 17, posY + 10, posZ + 6, Blocks.log, 1, 3);
					world.setBlock(posX + 17, posY + 10, posZ + 7, Blocks.log, 1, 3);
					world.setBlock(posX + 17, posY + 10, posZ + 8, Blocks.log, 1, 3);
					world.setBlock(posX + 17, posY + 10, posZ + 9, Blocks.planks, 1, 3);
					world.setBlock(posX + 17, posY + 10, posZ + 10, Blocks.planks, 1, 3);
					world.setBlock(posX + 17, posY + 10, posZ + 11, Blocks.planks, 1, 3);
					world.setBlock(posX + 17, posY + 10, posZ + 12, Blocks.planks, 1, 3);
					world.setBlock(posX + 17, posY + 10, posZ + 13, Blocks.planks, 1, 3);
					world.setBlock(posX + 17, posY + 10, posZ + 14, Blocks.planks, 1, 3);
					world.setBlock(posX + 17, posY + 10, posZ + 15, Blocks.planks, 1, 3);
					world.setBlock(posX + 17, posY + 10, posZ + 16, Blocks.planks, 1, 3);
					world.setBlock(posX + 17, posY + 10, posZ + 17, Blocks.planks, 1, 3);
					world.setBlock(posX + 17, posY + 10, posZ + 18, Blocks.planks, 1, 3);
					world.setBlock(posX + 17, posY + 10, posZ + 19, Blocks.planks, 1, 3);
					world.setBlock(posX + 17, posY + 10, posZ + 20, Blocks.planks, 1, 3);
					world.setBlock(posX + 17, posY + 10, posZ + 21, Blocks.planks, 1, 3);
					world.setBlock(posX + 17, posY + 10, posZ + 22, Blocks.planks, 1, 3);
					world.setBlock(posX + 17, posY + 10, posZ + 23, Blocks.planks, 1, 3);
					world.setBlock(posX + 17, posY + 10, posZ + 24, Blocks.planks, 1, 3);
					world.setBlock(posX + 17, posY + 10, posZ + 25, Blocks.planks, 1, 3);
					world.setBlock(posX + 17, posY + 10, posZ + 26, Blocks.planks, 1, 3);
					world.setBlock(posX + 17, posY + 10, posZ + 27, Blocks.planks, 1, 3);
					world.setBlock(posX + 17, posY + 10, posZ + 28, Blocks.planks, 1, 3);
					world.setBlock(posX + 17, posY + 10, posZ + 29, Blocks.planks, 1, 3);
					world.setBlock(posX + 17, posY + 10, posZ + 30, Blocks.planks, 1, 3);
					world.setBlock(posX + 17, posY + 10, posZ + 31, Blocks.planks, 1, 3);
					world.setBlock(posX + 17, posY + 10, posZ + 32, Blocks.planks, 1, 3);
					world.setBlock(posX + 17, posY + 10, posZ + 33, Blocks.planks, 1, 3);
					world.setBlock(posX + 17, posY + 10, posZ + 34, Blocks.planks, 1, 3);
					world.setBlock(posX + 17, posY + 10, posZ + 35, Blocks.planks, 1, 3);
					world.setBlock(posX + 17, posY + 10, posZ + 36, Blocks.planks, 1, 3);
					world.setBlock(posX + 17, posY + 10, posZ + 37, Blocks.planks, 1, 3);
					world.setBlock(posX + 17, posY + 10, posZ + 38, Blocks.planks, 1, 3);
					world.setBlock(posX + 17, posY + 10, posZ + 39, Blocks.planks, 1, 3);
					world.setBlock(posX + 17, posY + 10, posZ + 40, Blocks.planks, 1, 3);
					world.setBlock(posX + 17, posY + 10, posZ + 41, Blocks.planks, 1, 3);
					world.setBlock(posX + 17, posY + 10, posZ + 42, Blocks.planks, 1, 3);
					world.setBlock(posX + 17, posY + 10, posZ + 43, Blocks.planks, 1, 3);
					world.setBlock(posX + 17, posY + 10, posZ + 44, Blocks.planks, 1, 3);
					world.setBlock(posX + 17, posY + 10, posZ + 45, Blocks.planks, 1, 3);
					world.setBlock(posX + 17, posY + 10, posZ + 46, Blocks.planks, 1, 3);
					world.setBlock(posX + 17, posY + 10, posZ + 47, Blocks.planks, 1, 3);
					world.setBlock(posX + 17, posY + 11, posZ + 5, Blocks.fence, 0, 3);
					world.setBlock(posX + 17, posY + 11, posZ + 6, Blocks.fence, 0, 3);
					world.setBlock(posX + 17, posY + 11, posZ + 7, Blocks.fence, 0, 3);
					world.setBlock(posX + 17, posY + 11, posZ + 8, Blocks.fence, 0, 3);
					world.setBlock(posX + 17, posY + 11, posZ + 25, Blocks.log, 0, 3);
					world.setBlock(posX + 17, posY + 11, posZ + 26, Blocks.log, 0, 3);
					world.setBlock(posX + 17, posY + 11, posZ + 47, Blocks.planks, 1, 3);
					world.setBlock(posX + 17, posY + 12, posZ + 10, Blocks.stained_hardened_clay, 15, 3);
					world.setBlock(posX + 17, posY + 12, posZ + 11, Blocks.stained_hardened_clay, 15, 3);
					world.setBlock(posX + 17, posY + 12, posZ + 12, Blocks.stained_hardened_clay, 15, 3);
					world.setBlock(posX + 17, posY + 12, posZ + 25, Blocks.log, 0, 3);
					world.setBlock(posX + 17, posY + 12, posZ + 26, Blocks.log, 0, 3);
					world.setBlock(posX + 17, posY + 12, posZ + 47, Blocks.planks, 1, 3);
					world.setBlock(posX + 17, posY + 13, posZ + 25, Blocks.log, 0, 3);
					world.setBlock(posX + 17, posY + 13, posZ + 26, Blocks.log, 0, 3);
					world.setBlock(posX + 17, posY + 13, posZ + 39, Blocks.log, 1, 3);
					world.setBlock(posX + 17, posY + 13, posZ + 47, Blocks.planks, 1, 3);
					world.setBlock(posX + 17, posY + 14, posZ + 25, Blocks.log, 0, 3);
					world.setBlock(posX + 17, posY + 14, posZ + 26, Blocks.log, 0, 3);
					world.setBlock(posX + 17, posY + 14, posZ + 38, Blocks.wooden_slab, 1, 3);
					world.setBlock(posX + 17, posY + 14, posZ + 39, Blocks.planks, 1, 3);
					world.setBlock(posX + 17, posY + 14, posZ + 40, Blocks.planks, 1, 3);
					world.setBlock(posX + 17, posY + 14, posZ + 41, Blocks.planks, 1, 3);
					world.setBlock(posX + 17, posY + 14, posZ + 42, Blocks.planks, 1, 3);
					world.setBlock(posX + 17, posY + 14, posZ + 43, Blocks.planks, 1, 3);
					world.setBlock(posX + 17, posY + 14, posZ + 44, Blocks.planks, 1, 3);
					world.setBlock(posX + 17, posY + 14, posZ + 45, Blocks.planks, 1, 3);
					world.setBlock(posX + 17, posY + 14, posZ + 46, Blocks.planks, 1, 3);
					world.setBlock(posX + 17, posY + 14, posZ + 47, Blocks.planks, 1, 3);
					world.setBlock(posX + 17, posY + 15, posZ + 23, Blocks.fence, 0, 3);
					world.setBlock(posX + 17, posY + 15, posZ + 24, Blocks.fence, 0, 3);
					world.setBlock(posX + 17, posY + 15, posZ + 25, Blocks.log, 0, 3);
					world.setBlock(posX + 17, posY + 15, posZ + 26, Blocks.log, 0, 3);
					world.setBlock(posX + 17, posY + 15, posZ + 39, Blocks.fence, 0, 3);
					world.setBlock(posX + 17, posY + 15, posZ + 43, Blocks.oak_stairs, 2, 3);
					world.setBlock(posX + 17, posY + 15, posZ + 47, Blocks.fence, 0, 3);
